2024-01-11 08:48:27,810 - app - ERROR - Exception on /api/psychologist [GET]
Traceback (most recent call last):
  File "/Users/virender/Desktop/DriveKraft-Backend/venv/lib/python3.11/site-packages/flask/app.py", line 1455, in wsgi_app
    response = self.full_dispatch_request()
               ^^^^^^^^^^^^^^^^^^^^^^^^^^^^
  File "/Users/virender/Desktop/DriveKraft-Backend/venv/lib/python3.11/site-packages/flask/app.py", line 869, in full_dispatch_request
    rv = self.handle_user_exception(e)
         ^^^^^^^^^^^^^^^^^^^^^^^^^^^^^
  File "/Users/virender/Desktop/DriveKraft-Backend/venv/lib/python3.11/site-packages/flask/app.py", line 867, in full_dispatch_request
    rv = self.dispatch_request()
         ^^^^^^^^^^^^^^^^^^^^^^^
  File "/Users/virender/Desktop/DriveKraft-Backend/venv/lib/python3.11/site-packages/flask/app.py", line 852, in dispatch_request
    return self.ensure_sync(self.view_functions[rule.endpoint])(**view_args)
           ^^^^^^^^^^^^^^^^^^^^^^^^^^^^^^^^^^^^^^^^^^^^^^^^^^^^^^^^^^^^^^^^^
  File "/Users/virender/Desktop/DriveKraft-Backend/app/util.py", line 18, in wrapper
    raise e
  File "/Users/virender/Desktop/DriveKraft-Backend/app/util.py", line 12, in wrapper
    result = func(*args, **kwargs)
             ^^^^^^^^^^^^^^^^^^^^^
  File "/Users/virender/Desktop/DriveKraft-Backend/app/util.py", line 36, in wrapper
    return func(*args, **kwargs)
           ^^^^^^^^^^^^^^^^^^^^^
  File "/Users/virender/Desktop/DriveKraft-Backend/app/Routes/psychologistRoutes.py", line 16, in getAllPsychologist
    response = psychologistService.getAllPsychologist().__dict__
               ^^^^^^^^^^^^^^^^^^^^^^^^^^^^^^^^^^^^^^^^^^^^^^^^^
AttributeError: 'list' object has no attribute '__dict__'
