2024-01-18 03:39:58,887 - app - ERROR - Exception on /api/users/status/busy [POST]
Traceback (most recent call last):
  File "/home/DriveKraft/.local/lib/python3.10/site-packages/flask/app.py", line 2525, in wsgi_app
    response = self.full_dispatch_request()
  File "/home/DriveKraft/.local/lib/python3.10/site-packages/flask/app.py", line 1822, in full_dispatch_request
    rv = self.handle_user_exception(e)
  File "/home/DriveKraft/.local/lib/python3.10/site-packages/flask/app.py", line 1820, in full_dispatch_request
    rv = self.dispatch_request()
  File "/home/DriveKraft/.local/lib/python3.10/site-packages/flask/app.py", line 1796, in dispatch_request
    return self.ensure_sync(self.view_functions[rule.endpoint])(**view_args)
  File "/home/DriveKraft/drivekraft-app-backend/./app/util.py", line 21, in wrapper
    raise e
  File "/home/DriveKraft/drivekraft-app-backend/./app/util.py", line 15, in wrapper
    result = func(*args, **kwargs)
  File "/home/DriveKraft/drivekraft-app-backend/./app/authenticate.py", line 16, in wrapper
    return func(*args, **kwargs)
  File "/home/DriveKraft/drivekraft-app-backend/./app/util.py", line 43, in wrapper
    return func(*args, **kwargs)
  File "/home/DriveKraft/drivekraft-app-backend/./app/Routes/psychologistRoutes.py", line 30, in setPsychologistAsBusy
    response = psychologistService.setPsychologistBusy(requestData).__dict__
  File "/home/DriveKraft/drivekraft-app-backend/./app/Services/psychologistService.py", line 24, in setPsychologistBusy
    result = psychologistDao.updateBusyStatus(user.id,busyStatus)
  File "/home/DriveKraft/drivekraft-app-backend/./app/Models/DAO/psychologistDao.py", line 45, in updateBusyStatus
    psychologistData.isBusy = busy
  File "/usr/local/lib/python3.10/site-packages/sqlalchemy/engine/row.py", line 219, in __setattr__
    raise AttributeError("can't set attribute")
AttributeError: can't set attribute
2024-01-18 04:29:11,020 - app - ERROR - Exception on /api/user [GET]
Traceback (most recent call last):
  File "/usr/local/lib/python3.10/site-packages/sqlalchemy/engine/base.py", line 3280, in _wrap_pool_connect
    return fn()
  File "/usr/local/lib/python3.10/site-packages/sqlalchemy/pool/base.py", line 310, in connect
    return _ConnectionFairy._checkout(self)
  File "/usr/local/lib/python3.10/site-packages/sqlalchemy/pool/base.py", line 901, in _checkout
    result = pool._dialect.do_ping(fairy.dbapi_connection)
  File "/usr/local/lib/python3.10/site-packages/sqlalchemy/dialects/mysql/mysqldb.py", line 183, in do_ping
    dbapi_connection.ping(False)
MySQLdb._exceptions.OperationalError: (4031, 'The client was disconnected by the server because of inactivity. See wait_timeout and interactive_timeout for configuring this behavior.')

The above exception was the direct cause of the following exception:

Traceback (most recent call last):
  File "/home/DriveKraft/.local/lib/python3.10/site-packages/flask/app.py", line 2525, in wsgi_app
    response = self.full_dispatch_request()
  File "/home/DriveKraft/.local/lib/python3.10/site-packages/flask/app.py", line 1822, in full_dispatch_request
    rv = self.handle_user_exception(e)
  File "/home/DriveKraft/.local/lib/python3.10/site-packages/flask/app.py", line 1820, in full_dispatch_request
    rv = self.dispatch_request()
  File "/home/DriveKraft/.local/lib/python3.10/site-packages/flask/app.py", line 1796, in dispatch_request
    return self.ensure_sync(self.view_functions[rule.endpoint])(**view_args)
  File "/home/DriveKraft/drivekraft-app-backend/./app/util.py", line 43, in wrapper
    return func(*args, **kwargs)
  File "/home/DriveKraft/drivekraft-app-backend/./app/util.py", line 21, in wrapper
    raise e
  File "/home/DriveKraft/drivekraft-app-backend/./app/util.py", line 15, in wrapper
    result = func(*args, **kwargs)
  File "/home/DriveKraft/drivekraft-app-backend/./app/authenticate.py", line 14, in wrapper
    if verify_token(tokenValue):
  File "/home/DriveKraft/drivekraft-app-backend/./app/authenticate.py", line 25, in verify_token
    token = getToken(tokenValue=tokenValue)
  File "/home/DriveKraft/.local/lib/python3.10/site-packages/flask_caching/__init__.py", line 872, in decorated_function
    rv = self._call_fn(f, *args, **kwargs)
  File "/home/DriveKraft/.local/lib/python3.10/site-packages/flask_caching/__init__.py", line 175, in _call_fn
    return ensure_sync(fn)(*args, **kwargs)
  File "/home/DriveKraft/drivekraft-app-backend/./app/Models/DAO/tokenDAO.py", line 28, in getToken
    and_(Token.value == tokenValue, Token.created >= now - timedelta(hours=24))).one()
  File "/usr/local/lib/python3.10/site-packages/sqlalchemy/orm/query.py", line 2865, in one
    return self._iter().one()
  File "/usr/local/lib/python3.10/site-packages/sqlalchemy/orm/query.py", line 2903, in _iter
    result = self.session.execute(
  File "/usr/local/lib/python3.10/site-packages/sqlalchemy/orm/session.py", line 1695, in execute
    conn = self._connection_for_bind(bind)
  File "/usr/local/lib/python3.10/site-packages/sqlalchemy/orm/session.py", line 1536, in _connection_for_bind
    return self._transaction._connection_for_bind(
  File "/usr/local/lib/python3.10/site-packages/sqlalchemy/orm/session.py", line 747, in _connection_for_bind
    conn = bind.connect()
  File "/usr/local/lib/python3.10/site-packages/sqlalchemy/engine/base.py", line 3234, in connect
    return self._connection_cls(self, close_with_result=close_with_result)
  File "/usr/local/lib/python3.10/site-packages/sqlalchemy/engine/base.py", line 96, in __init__
    else engine.raw_connection()
  File "/usr/local/lib/python3.10/site-packages/sqlalchemy/engine/base.py", line 3313, in raw_connection
    return self._wrap_pool_connect(self.pool.connect, _connection)
  File "/usr/local/lib/python3.10/site-packages/sqlalchemy/engine/base.py", line 3283, in _wrap_pool_connect
    Connection._handle_dbapi_exception_noconnection(
  File "/usr/local/lib/python3.10/site-packages/sqlalchemy/engine/base.py", line 2117, in _handle_dbapi_exception_noconnection
    util.raise_(
  File "/usr/local/lib/python3.10/site-packages/sqlalchemy/util/compat.py", line 207, in raise_
    raise exception
  File "/usr/local/lib/python3.10/site-packages/sqlalchemy/engine/base.py", line 3280, in _wrap_pool_connect
    return fn()
  File "/usr/local/lib/python3.10/site-packages/sqlalchemy/pool/base.py", line 310, in connect
    return _ConnectionFairy._checkout(self)
  File "/usr/local/lib/python3.10/site-packages/sqlalchemy/pool/base.py", line 901, in _checkout
    result = pool._dialect.do_ping(fairy.dbapi_connection)
  File "/usr/local/lib/python3.10/site-packages/sqlalchemy/dialects/mysql/mysqldb.py", line 183, in do_ping
    dbapi_connection.ping(False)
sqlalchemy.exc.OperationalError: (MySQLdb._exceptions.OperationalError) (4031, 'The client was disconnected by the server because of inactivity. See wait_timeout and interactive_timeout for configuring this behavior.')
(Background on this error at: https://sqlalche.me/e/14/e3q8)
2024-01-18 04:29:29,741 - app - ERROR - Exception on /api/user [GET]
Traceback (most recent call last):
  File "/usr/local/lib/python3.10/site-packages/sqlalchemy/engine/base.py", line 3280, in _wrap_pool_connect
    return fn()
  File "/usr/local/lib/python3.10/site-packages/sqlalchemy/pool/base.py", line 310, in connect
    return _ConnectionFairy._checkout(self)
  File "/usr/local/lib/python3.10/site-packages/sqlalchemy/pool/base.py", line 901, in _checkout
    result = pool._dialect.do_ping(fairy.dbapi_connection)
  File "/usr/local/lib/python3.10/site-packages/sqlalchemy/dialects/mysql/mysqldb.py", line 183, in do_ping
    dbapi_connection.ping(False)
MySQLdb._exceptions.OperationalError: (4031, 'The client was disconnected by the server because of inactivity. See wait_timeout and interactive_timeout for configuring this behavior.')

The above exception was the direct cause of the following exception:

Traceback (most recent call last):
  File "/home/DriveKraft/.local/lib/python3.10/site-packages/flask/app.py", line 2525, in wsgi_app
    response = self.full_dispatch_request()
  File "/home/DriveKraft/.local/lib/python3.10/site-packages/flask/app.py", line 1822, in full_dispatch_request
    rv = self.handle_user_exception(e)
  File "/home/DriveKraft/.local/lib/python3.10/site-packages/flask/app.py", line 1820, in full_dispatch_request
    rv = self.dispatch_request()
  File "/home/DriveKraft/.local/lib/python3.10/site-packages/flask/app.py", line 1796, in dispatch_request
    return self.ensure_sync(self.view_functions[rule.endpoint])(**view_args)
  File "/home/DriveKraft/drivekraft-app-backend/./app/util.py", line 43, in wrapper
    return func(*args, **kwargs)
  File "/home/DriveKraft/drivekraft-app-backend/./app/util.py", line 21, in wrapper
    raise e
  File "/home/DriveKraft/drivekraft-app-backend/./app/util.py", line 15, in wrapper
    result = func(*args, **kwargs)
  File "/home/DriveKraft/drivekraft-app-backend/./app/authenticate.py", line 14, in wrapper
    if verify_token(tokenValue):
  File "/home/DriveKraft/drivekraft-app-backend/./app/authenticate.py", line 25, in verify_token
    token = getToken(tokenValue=tokenValue)
  File "/home/DriveKraft/.local/lib/python3.10/site-packages/flask_caching/__init__.py", line 872, in decorated_function
    rv = self._call_fn(f, *args, **kwargs)
  File "/home/DriveKraft/.local/lib/python3.10/site-packages/flask_caching/__init__.py", line 175, in _call_fn
    return ensure_sync(fn)(*args, **kwargs)
  File "/home/DriveKraft/drivekraft-app-backend/./app/Models/DAO/tokenDAO.py", line 28, in getToken
    and_(Token.value == tokenValue, Token.created >= now - timedelta(hours=24))).one()
  File "/usr/local/lib/python3.10/site-packages/sqlalchemy/orm/query.py", line 2865, in one
    return self._iter().one()
  File "/usr/local/lib/python3.10/site-packages/sqlalchemy/orm/query.py", line 2903, in _iter
    result = self.session.execute(
  File "/usr/local/lib/python3.10/site-packages/sqlalchemy/orm/session.py", line 1695, in execute
    conn = self._connection_for_bind(bind)
  File "/usr/local/lib/python3.10/site-packages/sqlalchemy/orm/session.py", line 1536, in _connection_for_bind
    return self._transaction._connection_for_bind(
  File "/usr/local/lib/python3.10/site-packages/sqlalchemy/orm/session.py", line 747, in _connection_for_bind
    conn = bind.connect()
  File "/usr/local/lib/python3.10/site-packages/sqlalchemy/engine/base.py", line 3234, in connect
    return self._connection_cls(self, close_with_result=close_with_result)
  File "/usr/local/lib/python3.10/site-packages/sqlalchemy/engine/base.py", line 96, in __init__
    else engine.raw_connection()
  File "/usr/local/lib/python3.10/site-packages/sqlalchemy/engine/base.py", line 3313, in raw_connection
    return self._wrap_pool_connect(self.pool.connect, _connection)
  File "/usr/local/lib/python3.10/site-packages/sqlalchemy/engine/base.py", line 3283, in _wrap_pool_connect
    Connection._handle_dbapi_exception_noconnection(
  File "/usr/local/lib/python3.10/site-packages/sqlalchemy/engine/base.py", line 2117, in _handle_dbapi_exception_noconnection
    util.raise_(
  File "/usr/local/lib/python3.10/site-packages/sqlalchemy/util/compat.py", line 207, in raise_
    raise exception
  File "/usr/local/lib/python3.10/site-packages/sqlalchemy/engine/base.py", line 3280, in _wrap_pool_connect
    return fn()
  File "/usr/local/lib/python3.10/site-packages/sqlalchemy/pool/base.py", line 310, in connect
    return _ConnectionFairy._checkout(self)
  File "/usr/local/lib/python3.10/site-packages/sqlalchemy/pool/base.py", line 901, in _checkout
    result = pool._dialect.do_ping(fairy.dbapi_connection)
  File "/usr/local/lib/python3.10/site-packages/sqlalchemy/dialects/mysql/mysqldb.py", line 183, in do_ping
    dbapi_connection.ping(False)
sqlalchemy.exc.OperationalError: (MySQLdb._exceptions.OperationalError) (4031, 'The client was disconnected by the server because of inactivity. See wait_timeout and interactive_timeout for configuring this behavior.')
(Background on this error at: https://sqlalche.me/e/14/e3q8)
2024-01-18 17:08:53,889 - app - ERROR - Exception on /api/users/status/busy [POST]
Traceback (most recent call last):
  File "/home/DriveKraft/.local/lib/python3.10/site-packages/flask/app.py", line 2525, in wsgi_app
    response = self.full_dispatch_request()
  File "/home/DriveKraft/.local/lib/python3.10/site-packages/flask/app.py", line 1822, in full_dispatch_request
    rv = self.handle_user_exception(e)
  File "/home/DriveKraft/.local/lib/python3.10/site-packages/flask/app.py", line 1820, in full_dispatch_request
    rv = self.dispatch_request()
  File "/home/DriveKraft/.local/lib/python3.10/site-packages/flask/app.py", line 1796, in dispatch_request
    return self.ensure_sync(self.view_functions[rule.endpoint])(**view_args)
  File "/home/DriveKraft/drivekraft-app-backend/./app/util.py", line 21, in wrapper
    raise e
  File "/home/DriveKraft/drivekraft-app-backend/./app/util.py", line 15, in wrapper
    result = func(*args, **kwargs)
  File "/home/DriveKraft/drivekraft-app-backend/./app/authenticate.py", line 16, in wrapper
    return func(*args, **kwargs)
  File "/home/DriveKraft/drivekraft-app-backend/./app/util.py", line 43, in wrapper
    return func(*args, **kwargs)
  File "/home/DriveKraft/drivekraft-app-backend/./app/Routes/psychologistRoutes.py", line 30, in setPsychologistAsBusy
    response = psychologistService.setPsychologistBusy(requestData).__dict__
  File "/home/DriveKraft/drivekraft-app-backend/./app/Services/psychologistService.py", line 24, in setPsychologistBusy
    result = psychologistDao.updateBusyStatus(user.id,busyStatus)
  File "/home/DriveKraft/drivekraft-app-backend/./app/Models/DAO/psychologistDao.py", line 45, in updateBusyStatus
    psychologistData.isBusy = busy
  File "/usr/local/lib/python3.10/site-packages/sqlalchemy/engine/row.py", line 219, in __setattr__
    raise AttributeError("can't set attribute")
AttributeError: can't set attribute
2024-01-18 17:09:27,718 - app - ERROR - Exception on /api/session/book/request [POST]
Traceback (most recent call last):
  File "/home/DriveKraft/.local/lib/python3.10/site-packages/flask/app.py", line 2525, in wsgi_app
    response = self.full_dispatch_request()
  File "/home/DriveKraft/.local/lib/python3.10/site-packages/flask/app.py", line 1822, in full_dispatch_request
    rv = self.handle_user_exception(e)
  File "/home/DriveKraft/.local/lib/python3.10/site-packages/flask/app.py", line 1820, in full_dispatch_request
    rv = self.dispatch_request()
  File "/home/DriveKraft/.local/lib/python3.10/site-packages/flask/app.py", line 1796, in dispatch_request
    return self.ensure_sync(self.view_functions[rule.endpoint])(**view_args)
  File "/home/DriveKraft/drivekraft-app-backend/./app/util.py", line 21, in wrapper
    raise e
  File "/home/DriveKraft/drivekraft-app-backend/./app/util.py", line 15, in wrapper
    result = func(*args, **kwargs)
  File "/home/DriveKraft/drivekraft-app-backend/./app/util.py", line 43, in wrapper
    return func(*args, **kwargs)
  File "/home/DriveKraft/drivekraft-app-backend/./app/authenticate.py", line 16, in wrapper
    return func(*args, **kwargs)
  File "/home/DriveKraft/drivekraft-app-backend/./app/Routes/sessionRoutes.py", line 16, in sendSessionRequestFun
    response = sessionService.send_Session_Request(sessionCreationRequest).__dict__
  File "/home/DriveKraft/drivekraft-app-backend/./app/Services/sessionService.py", line 32, in send_Session_Request
    response = sendSessionResponse(id=userCurrentSession.id)
AttributeError: 'NoneType' object has no attribute 'id'
2024-01-18 17:21:47,419 - app - ERROR - Exception on /api/role [GET]
Traceback (most recent call last):
  File "/usr/local/lib/python3.10/site-packages/sqlalchemy/engine/base.py", line 3280, in _wrap_pool_connect
    return fn()
  File "/usr/local/lib/python3.10/site-packages/sqlalchemy/pool/base.py", line 310, in connect
    return _ConnectionFairy._checkout(self)
  File "/usr/local/lib/python3.10/site-packages/sqlalchemy/pool/base.py", line 901, in _checkout
    result = pool._dialect.do_ping(fairy.dbapi_connection)
  File "/usr/local/lib/python3.10/site-packages/sqlalchemy/dialects/mysql/mysqldb.py", line 183, in do_ping
    dbapi_connection.ping(False)
MySQLdb._exceptions.OperationalError: (4031, 'The client was disconnected by the server because of inactivity. See wait_timeout and interactive_timeout for configuring this behavior.')

The above exception was the direct cause of the following exception:

Traceback (most recent call last):
  File "/home/DriveKraft/.local/lib/python3.10/site-packages/flask/app.py", line 2525, in wsgi_app
    response = self.full_dispatch_request()
  File "/home/DriveKraft/.local/lib/python3.10/site-packages/flask/app.py", line 1822, in full_dispatch_request
    rv = self.handle_user_exception(e)
  File "/home/DriveKraft/.local/lib/python3.10/site-packages/flask/app.py", line 1820, in full_dispatch_request
    rv = self.dispatch_request()
  File "/home/DriveKraft/.local/lib/python3.10/site-packages/flask/app.py", line 1796, in dispatch_request
    return self.ensure_sync(self.view_functions[rule.endpoint])(**view_args)
  File "/home/DriveKraft/drivekraft-app-backend/./app/util.py", line 21, in wrapper
    raise e
  File "/home/DriveKraft/drivekraft-app-backend/./app/util.py", line 15, in wrapper
    result = func(*args, **kwargs)
  File "/home/DriveKraft/drivekraft-app-backend/./app/authenticate.py", line 14, in wrapper
    if verify_token(tokenValue):
  File "/home/DriveKraft/drivekraft-app-backend/./app/authenticate.py", line 25, in verify_token
    token = getToken(tokenValue=tokenValue)
  File "/home/DriveKraft/.local/lib/python3.10/site-packages/flask_caching/__init__.py", line 872, in decorated_function
    rv = self._call_fn(f, *args, **kwargs)
  File "/home/DriveKraft/.local/lib/python3.10/site-packages/flask_caching/__init__.py", line 175, in _call_fn
    return ensure_sync(fn)(*args, **kwargs)
  File "/home/DriveKraft/drivekraft-app-backend/./app/Models/DAO/tokenDAO.py", line 28, in getToken
    and_(Token.value == tokenValue, Token.created >= now - timedelta(hours=24))).one()
  File "/usr/local/lib/python3.10/site-packages/sqlalchemy/orm/query.py", line 2865, in one
    return self._iter().one()
  File "/usr/local/lib/python3.10/site-packages/sqlalchemy/orm/query.py", line 2903, in _iter
    result = self.session.execute(
  File "/usr/local/lib/python3.10/site-packages/sqlalchemy/orm/session.py", line 1695, in execute
    conn = self._connection_for_bind(bind)
  File "/usr/local/lib/python3.10/site-packages/sqlalchemy/orm/session.py", line 1536, in _connection_for_bind
    return self._transaction._connection_for_bind(
  File "/usr/local/lib/python3.10/site-packages/sqlalchemy/orm/session.py", line 747, in _connection_for_bind
    conn = bind.connect()
  File "/usr/local/lib/python3.10/site-packages/sqlalchemy/engine/base.py", line 3234, in connect
    return self._connection_cls(self, close_with_result=close_with_result)
  File "/usr/local/lib/python3.10/site-packages/sqlalchemy/engine/base.py", line 96, in __init__
    else engine.raw_connection()
  File "/usr/local/lib/python3.10/site-packages/sqlalchemy/engine/base.py", line 3313, in raw_connection
    return self._wrap_pool_connect(self.pool.connect, _connection)
  File "/usr/local/lib/python3.10/site-packages/sqlalchemy/engine/base.py", line 3283, in _wrap_pool_connect
    Connection._handle_dbapi_exception_noconnection(
  File "/usr/local/lib/python3.10/site-packages/sqlalchemy/engine/base.py", line 2117, in _handle_dbapi_exception_noconnection
    util.raise_(
  File "/usr/local/lib/python3.10/site-packages/sqlalchemy/util/compat.py", line 207, in raise_
    raise exception
  File "/usr/local/lib/python3.10/site-packages/sqlalchemy/engine/base.py", line 3280, in _wrap_pool_connect
    return fn()
  File "/usr/local/lib/python3.10/site-packages/sqlalchemy/pool/base.py", line 310, in connect
    return _ConnectionFairy._checkout(self)
  File "/usr/local/lib/python3.10/site-packages/sqlalchemy/pool/base.py", line 901, in _checkout
    result = pool._dialect.do_ping(fairy.dbapi_connection)
  File "/usr/local/lib/python3.10/site-packages/sqlalchemy/dialects/mysql/mysqldb.py", line 183, in do_ping
    dbapi_connection.ping(False)
sqlalchemy.exc.OperationalError: (MySQLdb._exceptions.OperationalError) (4031, 'The client was disconnected by the server because of inactivity. See wait_timeout and interactive_timeout for configuring this behavior.')
(Background on this error at: https://sqlalche.me/e/14/e3q8)
2024-01-18 17:45:02,508 - app - ERROR - Exception on /api/login-send-otp [POST]
Traceback (most recent call last):
  File "/usr/local/lib/python3.10/site-packages/sqlalchemy/engine/base.py", line 3280, in _wrap_pool_connect
    return fn()
  File "/usr/local/lib/python3.10/site-packages/sqlalchemy/pool/base.py", line 310, in connect
    return _ConnectionFairy._checkout(self)
  File "/usr/local/lib/python3.10/site-packages/sqlalchemy/pool/base.py", line 901, in _checkout
    result = pool._dialect.do_ping(fairy.dbapi_connection)
  File "/usr/local/lib/python3.10/site-packages/sqlalchemy/dialects/mysql/mysqldb.py", line 183, in do_ping
    dbapi_connection.ping(False)
MySQLdb._exceptions.OperationalError: (4031, 'The client was disconnected by the server because of inactivity. See wait_timeout and interactive_timeout for configuring this behavior.')

The above exception was the direct cause of the following exception:

Traceback (most recent call last):
  File "/home/DriveKraft/.local/lib/python3.10/site-packages/flask/app.py", line 2525, in wsgi_app
    response = self.full_dispatch_request()
  File "/home/DriveKraft/.local/lib/python3.10/site-packages/flask/app.py", line 1822, in full_dispatch_request
    rv = self.handle_user_exception(e)
  File "/home/DriveKraft/.local/lib/python3.10/site-packages/flask/app.py", line 1820, in full_dispatch_request
    rv = self.dispatch_request()
  File "/home/DriveKraft/.local/lib/python3.10/site-packages/flask/app.py", line 1796, in dispatch_request
    return self.ensure_sync(self.view_functions[rule.endpoint])(**view_args)
  File "/home/DriveKraft/drivekraft-app-backend/./app/util.py", line 21, in wrapper
    raise e
  File "/home/DriveKraft/drivekraft-app-backend/./app/util.py", line 15, in wrapper
    result = func(*args, **kwargs)
  File "/home/DriveKraft/drivekraft-app-backend/./app/util.py", line 43, in wrapper
    return func(*args, **kwargs)
  File "/home/DriveKraft/drivekraft-app-backend/./app/Routes/otpRoutes.py", line 19, in generateNewOtp
    response = otpGenerateService.generateOtp(otpRequest).__dict__
  File "/home/DriveKraft/drivekraft-app-backend/./app/Services/otpGenerateService.py", line 23, in generateOtp
    user = userService.getUserByContact(contactNumber=request.mobile)
  File "/home/DriveKraft/drivekraft-app-backend/./app/Services/userService.py", line 84, in getUserByContact
    return userDao.getUserByContact(contactNumber)
  File "/home/DriveKraft/drivekraft-app-backend/./app/Models/DAO/userDao.py", line 44, in getUserByContact
    user = session.query(User).filter_by(contactNumber=contactNumber).one()
  File "/usr/local/lib/python3.10/site-packages/sqlalchemy/orm/query.py", line 2865, in one
    return self._iter().one()
  File "/usr/local/lib/python3.10/site-packages/sqlalchemy/orm/query.py", line 2903, in _iter
    result = self.session.execute(
  File "/usr/local/lib/python3.10/site-packages/sqlalchemy/orm/session.py", line 1695, in execute
    conn = self._connection_for_bind(bind)
  File "/usr/local/lib/python3.10/site-packages/sqlalchemy/orm/session.py", line 1536, in _connection_for_bind
    return self._transaction._connection_for_bind(
  File "/usr/local/lib/python3.10/site-packages/sqlalchemy/orm/session.py", line 747, in _connection_for_bind
    conn = bind.connect()
  File "/usr/local/lib/python3.10/site-packages/sqlalchemy/engine/base.py", line 3234, in connect
    return self._connection_cls(self, close_with_result=close_with_result)
  File "/usr/local/lib/python3.10/site-packages/sqlalchemy/engine/base.py", line 96, in __init__
    else engine.raw_connection()
  File "/usr/local/lib/python3.10/site-packages/sqlalchemy/engine/base.py", line 3313, in raw_connection
    return self._wrap_pool_connect(self.pool.connect, _connection)
  File "/usr/local/lib/python3.10/site-packages/sqlalchemy/engine/base.py", line 3283, in _wrap_pool_connect
    Connection._handle_dbapi_exception_noconnection(
  File "/usr/local/lib/python3.10/site-packages/sqlalchemy/engine/base.py", line 2117, in _handle_dbapi_exception_noconnection
    util.raise_(
  File "/usr/local/lib/python3.10/site-packages/sqlalchemy/util/compat.py", line 207, in raise_
    raise exception
  File "/usr/local/lib/python3.10/site-packages/sqlalchemy/engine/base.py", line 3280, in _wrap_pool_connect
    return fn()
  File "/usr/local/lib/python3.10/site-packages/sqlalchemy/pool/base.py", line 310, in connect
    return _ConnectionFairy._checkout(self)
  File "/usr/local/lib/python3.10/site-packages/sqlalchemy/pool/base.py", line 901, in _checkout
    result = pool._dialect.do_ping(fairy.dbapi_connection)
  File "/usr/local/lib/python3.10/site-packages/sqlalchemy/dialects/mysql/mysqldb.py", line 183, in do_ping
    dbapi_connection.ping(False)
sqlalchemy.exc.OperationalError: (MySQLdb._exceptions.OperationalError) (4031, 'The client was disconnected by the server because of inactivity. See wait_timeout and interactive_timeout for configuring this behavior.')
(Background on this error at: https://sqlalche.me/e/14/e3q8)
2024-01-18 17:46:57,807 - app - ERROR - Exception on /api/users/status/busy [POST]
Traceback (most recent call last):
  File "/home/DriveKraft/.local/lib/python3.10/site-packages/flask/app.py", line 2525, in wsgi_app
    response = self.full_dispatch_request()
  File "/home/DriveKraft/.local/lib/python3.10/site-packages/flask/app.py", line 1822, in full_dispatch_request
    rv = self.handle_user_exception(e)
  File "/home/DriveKraft/.local/lib/python3.10/site-packages/flask/app.py", line 1820, in full_dispatch_request
    rv = self.dispatch_request()
  File "/home/DriveKraft/.local/lib/python3.10/site-packages/flask/app.py", line 1796, in dispatch_request
    return self.ensure_sync(self.view_functions[rule.endpoint])(**view_args)
  File "/home/DriveKraft/drivekraft-app-backend/./app/util.py", line 21, in wrapper
    raise e
  File "/home/DriveKraft/drivekraft-app-backend/./app/util.py", line 15, in wrapper
    result = func(*args, **kwargs)
  File "/home/DriveKraft/drivekraft-app-backend/./app/authenticate.py", line 16, in wrapper
    return func(*args, **kwargs)
  File "/home/DriveKraft/drivekraft-app-backend/./app/util.py", line 43, in wrapper
    return func(*args, **kwargs)
  File "/home/DriveKraft/drivekraft-app-backend/./app/Routes/psychologistRoutes.py", line 30, in setPsychologistAsBusy
    response = psychologistService.setPsychologistBusy(requestData).__dict__
  File "/home/DriveKraft/drivekraft-app-backend/./app/Services/psychologistService.py", line 24, in setPsychologistBusy
    result = psychologistDao.updateBusyStatus(user.id,busyStatus)
  File "/home/DriveKraft/drivekraft-app-backend/./app/Models/DAO/psychologistDao.py", line 45, in updateBusyStatus
    psychologistData.isBusy = busy
  File "/usr/local/lib/python3.10/site-packages/sqlalchemy/engine/row.py", line 219, in __setattr__
    raise AttributeError("can't set attribute")
AttributeError: can't set attribute
2024-01-18 17:47:05,176 - app - ERROR - Exception on /api/session/book/request [POST]
Traceback (most recent call last):
  File "/home/DriveKraft/.local/lib/python3.10/site-packages/flask/app.py", line 2525, in wsgi_app
    response = self.full_dispatch_request()
  File "/home/DriveKraft/.local/lib/python3.10/site-packages/flask/app.py", line 1822, in full_dispatch_request
    rv = self.handle_user_exception(e)
  File "/home/DriveKraft/.local/lib/python3.10/site-packages/flask/app.py", line 1820, in full_dispatch_request
    rv = self.dispatch_request()
  File "/home/DriveKraft/.local/lib/python3.10/site-packages/flask/app.py", line 1796, in dispatch_request
    return self.ensure_sync(self.view_functions[rule.endpoint])(**view_args)
  File "/home/DriveKraft/drivekraft-app-backend/./app/util.py", line 21, in wrapper
    raise e
  File "/home/DriveKraft/drivekraft-app-backend/./app/util.py", line 15, in wrapper
    result = func(*args, **kwargs)
  File "/home/DriveKraft/drivekraft-app-backend/./app/util.py", line 43, in wrapper
    return func(*args, **kwargs)
  File "/home/DriveKraft/drivekraft-app-backend/./app/authenticate.py", line 16, in wrapper
    return func(*args, **kwargs)
  File "/home/DriveKraft/drivekraft-app-backend/./app/Routes/sessionRoutes.py", line 16, in sendSessionRequestFun
    response = sessionService.send_Session_Request(sessionCreationRequest).__dict__
  File "/home/DriveKraft/drivekraft-app-backend/./app/Services/sessionService.py", line 32, in send_Session_Request
    response = sendSessionResponse(id=userCurrentSession.id)
AttributeError: 'NoneType' object has no attribute 'id'
2024-01-18 17:58:22,699 - app - ERROR - Exception on /api/session/book/request [POST]
Traceback (most recent call last):
  File "/home/DriveKraft/.local/lib/python3.10/site-packages/flask/app.py", line 2525, in wsgi_app
    response = self.full_dispatch_request()
  File "/home/DriveKraft/.local/lib/python3.10/site-packages/flask/app.py", line 1822, in full_dispatch_request
    rv = self.handle_user_exception(e)
  File "/home/DriveKraft/.local/lib/python3.10/site-packages/flask/app.py", line 1820, in full_dispatch_request
    rv = self.dispatch_request()
  File "/home/DriveKraft/.local/lib/python3.10/site-packages/flask/app.py", line 1796, in dispatch_request
    return self.ensure_sync(self.view_functions[rule.endpoint])(**view_args)
  File "/home/DriveKraft/drivekraft-app-backend/./app/util.py", line 21, in wrapper
    raise e
  File "/home/DriveKraft/drivekraft-app-backend/./app/util.py", line 15, in wrapper
    result = func(*args, **kwargs)
  File "/home/DriveKraft/drivekraft-app-backend/./app/util.py", line 43, in wrapper
    return func(*args, **kwargs)
  File "/home/DriveKraft/drivekraft-app-backend/./app/authenticate.py", line 16, in wrapper
    return func(*args, **kwargs)
  File "/home/DriveKraft/drivekraft-app-backend/./app/Routes/sessionRoutes.py", line 16, in sendSessionRequestFun
    response = sessionService.send_Session_Request(sessionCreationRequest).__dict__
  File "/home/DriveKraft/drivekraft-app-backend/./app/Services/sessionService.py", line 32, in send_Session_Request
    response = sendSessionResponse(id=userCurrentSession.id)
AttributeError: 'NoneType' object has no attribute 'id'
2024-01-18 18:05:38,880 - app - ERROR - Exception on /api/role [GET]
Traceback (most recent call last):
  File "/usr/local/lib/python3.10/site-packages/sqlalchemy/engine/base.py", line 3280, in _wrap_pool_connect
    return fn()
  File "/usr/local/lib/python3.10/site-packages/sqlalchemy/pool/base.py", line 310, in connect
    return _ConnectionFairy._checkout(self)
  File "/usr/local/lib/python3.10/site-packages/sqlalchemy/pool/base.py", line 901, in _checkout
    result = pool._dialect.do_ping(fairy.dbapi_connection)
  File "/usr/local/lib/python3.10/site-packages/sqlalchemy/dialects/mysql/mysqldb.py", line 183, in do_ping
    dbapi_connection.ping(False)
MySQLdb._exceptions.OperationalError: (4031, 'The client was disconnected by the server because of inactivity. See wait_timeout and interactive_timeout for configuring this behavior.')

The above exception was the direct cause of the following exception:

Traceback (most recent call last):
  File "/home/DriveKraft/.local/lib/python3.10/site-packages/flask/app.py", line 2525, in wsgi_app
    response = self.full_dispatch_request()
  File "/home/DriveKraft/.local/lib/python3.10/site-packages/flask/app.py", line 1822, in full_dispatch_request
    rv = self.handle_user_exception(e)
  File "/home/DriveKraft/.local/lib/python3.10/site-packages/flask/app.py", line 1820, in full_dispatch_request
    rv = self.dispatch_request()
  File "/home/DriveKraft/.local/lib/python3.10/site-packages/flask/app.py", line 1796, in dispatch_request
    return self.ensure_sync(self.view_functions[rule.endpoint])(**view_args)
  File "/home/DriveKraft/drivekraft-app-backend/./app/util.py", line 21, in wrapper
    raise e
  File "/home/DriveKraft/drivekraft-app-backend/./app/util.py", line 15, in wrapper
    result = func(*args, **kwargs)
  File "/home/DriveKraft/drivekraft-app-backend/./app/authenticate.py", line 16, in wrapper
    return func(*args, **kwargs)
  File "/home/DriveKraft/drivekraft-app-backend/./app/util.py", line 43, in wrapper
    return func(*args, **kwargs)
  File "/home/DriveKraft/drivekraft-app-backend/./app/Routes/roleRoutes.py", line 15, in getRole
    response = roleService.getUserRole().to_dict()
  File "/home/DriveKraft/drivekraft-app-backend/./app/Services/roleService.py", line 9, in getUserRole
    user = userService.getUserDetails()
  File "/home/DriveKraft/drivekraft-app-backend/./app/Services/userService.py", line 100, in getUserDetails
    user = getUserByToken(g.tokenValue)
  File "/home/DriveKraft/drivekraft-app-backend/./app/Services/userService.py", line 96, in getUserByToken
    return userDao.getUserById(token.userId)
  File "/home/DriveKraft/drivekraft-app-backend/./app/Models/DAO/userDao.py", line 53, in getUserById
    user = session.query(User).filter_by(id=userId).one()
  File "/usr/local/lib/python3.10/site-packages/sqlalchemy/orm/query.py", line 2865, in one
    return self._iter().one()
  File "/usr/local/lib/python3.10/site-packages/sqlalchemy/orm/query.py", line 2903, in _iter
    result = self.session.execute(
  File "/usr/local/lib/python3.10/site-packages/sqlalchemy/orm/session.py", line 1695, in execute
    conn = self._connection_for_bind(bind)
  File "/usr/local/lib/python3.10/site-packages/sqlalchemy/orm/session.py", line 1536, in _connection_for_bind
    return self._transaction._connection_for_bind(
  File "/usr/local/lib/python3.10/site-packages/sqlalchemy/orm/session.py", line 747, in _connection_for_bind
    conn = bind.connect()
  File "/usr/local/lib/python3.10/site-packages/sqlalchemy/engine/base.py", line 3234, in connect
    return self._connection_cls(self, close_with_result=close_with_result)
  File "/usr/local/lib/python3.10/site-packages/sqlalchemy/engine/base.py", line 96, in __init__
    else engine.raw_connection()
  File "/usr/local/lib/python3.10/site-packages/sqlalchemy/engine/base.py", line 3313, in raw_connection
    return self._wrap_pool_connect(self.pool.connect, _connection)
  File "/usr/local/lib/python3.10/site-packages/sqlalchemy/engine/base.py", line 3283, in _wrap_pool_connect
    Connection._handle_dbapi_exception_noconnection(
  File "/usr/local/lib/python3.10/site-packages/sqlalchemy/engine/base.py", line 2117, in _handle_dbapi_exception_noconnection
    util.raise_(
  File "/usr/local/lib/python3.10/site-packages/sqlalchemy/util/compat.py", line 207, in raise_
    raise exception
  File "/usr/local/lib/python3.10/site-packages/sqlalchemy/engine/base.py", line 3280, in _wrap_pool_connect
    return fn()
  File "/usr/local/lib/python3.10/site-packages/sqlalchemy/pool/base.py", line 310, in connect
    return _ConnectionFairy._checkout(self)
  File "/usr/local/lib/python3.10/site-packages/sqlalchemy/pool/base.py", line 901, in _checkout
    result = pool._dialect.do_ping(fairy.dbapi_connection)
  File "/usr/local/lib/python3.10/site-packages/sqlalchemy/dialects/mysql/mysqldb.py", line 183, in do_ping
    dbapi_connection.ping(False)
sqlalchemy.exc.OperationalError: (MySQLdb._exceptions.OperationalError) (4031, 'The client was disconnected by the server because of inactivity. See wait_timeout and interactive_timeout for configuring this behavior.')
(Background on this error at: https://sqlalche.me/e/14/e3q8)
2024-01-18 18:15:02,237 - app - ERROR - Exception on /api/session/book/request [POST]
Traceback (most recent call last):
  File "/home/DriveKraft/.local/lib/python3.10/site-packages/flask/app.py", line 2525, in wsgi_app
    response = self.full_dispatch_request()
  File "/home/DriveKraft/.local/lib/python3.10/site-packages/flask/app.py", line 1822, in full_dispatch_request
    rv = self.handle_user_exception(e)
  File "/home/DriveKraft/.local/lib/python3.10/site-packages/flask/app.py", line 1820, in full_dispatch_request
    rv = self.dispatch_request()
  File "/home/DriveKraft/.local/lib/python3.10/site-packages/flask/app.py", line 1796, in dispatch_request
    return self.ensure_sync(self.view_functions[rule.endpoint])(**view_args)
  File "/home/DriveKraft/drivekraft-app-backend/./app/util.py", line 21, in wrapper
    raise e
  File "/home/DriveKraft/drivekraft-app-backend/./app/util.py", line 15, in wrapper
    result = func(*args, **kwargs)
  File "/home/DriveKraft/drivekraft-app-backend/./app/util.py", line 43, in wrapper
    return func(*args, **kwargs)
  File "/home/DriveKraft/drivekraft-app-backend/./app/authenticate.py", line 16, in wrapper
    return func(*args, **kwargs)
  File "/home/DriveKraft/drivekraft-app-backend/./app/Routes/sessionRoutes.py", line 16, in sendSessionRequestFun
    response = sessionService.send_Session_Request(sessionCreationRequest).__dict__
  File "/home/DriveKraft/drivekraft-app-backend/./app/Services/sessionService.py", line 32, in send_Session_Request
    response = sendSessionResponse(id=userCurrentSession.id)
AttributeError: 'NoneType' object has no attribute 'id'
2024-01-18 18:15:07,672 - app - ERROR - Exception on /api/session/book/request [POST]
Traceback (most recent call last):
  File "/home/DriveKraft/.local/lib/python3.10/site-packages/flask/app.py", line 2525, in wsgi_app
    response = self.full_dispatch_request()
  File "/home/DriveKraft/.local/lib/python3.10/site-packages/flask/app.py", line 1822, in full_dispatch_request
    rv = self.handle_user_exception(e)
  File "/home/DriveKraft/.local/lib/python3.10/site-packages/flask/app.py", line 1820, in full_dispatch_request
    rv = self.dispatch_request()
  File "/home/DriveKraft/.local/lib/python3.10/site-packages/flask/app.py", line 1796, in dispatch_request
    return self.ensure_sync(self.view_functions[rule.endpoint])(**view_args)
  File "/home/DriveKraft/drivekraft-app-backend/./app/util.py", line 21, in wrapper
    raise e
  File "/home/DriveKraft/drivekraft-app-backend/./app/util.py", line 15, in wrapper
    result = func(*args, **kwargs)
  File "/home/DriveKraft/drivekraft-app-backend/./app/util.py", line 43, in wrapper
    return func(*args, **kwargs)
  File "/home/DriveKraft/drivekraft-app-backend/./app/authenticate.py", line 16, in wrapper
    return func(*args, **kwargs)
  File "/home/DriveKraft/drivekraft-app-backend/./app/Routes/sessionRoutes.py", line 16, in sendSessionRequestFun
    response = sessionService.send_Session_Request(sessionCreationRequest).__dict__
  File "/home/DriveKraft/drivekraft-app-backend/./app/Services/sessionService.py", line 32, in send_Session_Request
    response = sendSessionResponse(id=userCurrentSession.id)
AttributeError: 'NoneType' object has no attribute 'id'
2024-01-18 18:15:49,144 - app - ERROR - Exception on /api/session/book/request [POST]
Traceback (most recent call last):
  File "/home/DriveKraft/.local/lib/python3.10/site-packages/flask/app.py", line 2525, in wsgi_app
    response = self.full_dispatch_request()
  File "/home/DriveKraft/.local/lib/python3.10/site-packages/flask/app.py", line 1822, in full_dispatch_request
    rv = self.handle_user_exception(e)
  File "/home/DriveKraft/.local/lib/python3.10/site-packages/flask/app.py", line 1820, in full_dispatch_request
    rv = self.dispatch_request()
  File "/home/DriveKraft/.local/lib/python3.10/site-packages/flask/app.py", line 1796, in dispatch_request
    return self.ensure_sync(self.view_functions[rule.endpoint])(**view_args)
  File "/home/DriveKraft/drivekraft-app-backend/./app/util.py", line 21, in wrapper
    raise e
  File "/home/DriveKraft/drivekraft-app-backend/./app/util.py", line 15, in wrapper
    result = func(*args, **kwargs)
  File "/home/DriveKraft/drivekraft-app-backend/./app/util.py", line 43, in wrapper
    return func(*args, **kwargs)
  File "/home/DriveKraft/drivekraft-app-backend/./app/authenticate.py", line 16, in wrapper
    return func(*args, **kwargs)
  File "/home/DriveKraft/drivekraft-app-backend/./app/Routes/sessionRoutes.py", line 16, in sendSessionRequestFun
    response = sessionService.send_Session_Request(sessionCreationRequest).__dict__
  File "/home/DriveKraft/drivekraft-app-backend/./app/Services/sessionService.py", line 32, in send_Session_Request
    response = sendSessionResponse(id=userCurrentSession.id)
AttributeError: 'NoneType' object has no attribute 'id'
2024-01-18 18:23:00,691 - app - ERROR - Exception on /api/session/request/fetch [GET]
Traceback (most recent call last):
  File "/home/DriveKraft/.local/lib/python3.10/site-packages/flask/app.py", line 2525, in wsgi_app
    response = self.full_dispatch_request()
  File "/home/DriveKraft/.local/lib/python3.10/site-packages/flask/app.py", line 1822, in full_dispatch_request
    rv = self.handle_user_exception(e)
  File "/home/DriveKraft/.local/lib/python3.10/site-packages/flask/app.py", line 1820, in full_dispatch_request
    rv = self.dispatch_request()
  File "/home/DriveKraft/.local/lib/python3.10/site-packages/flask/app.py", line 1796, in dispatch_request
    return self.ensure_sync(self.view_functions[rule.endpoint])(**view_args)
  File "/home/DriveKraft/drivekraft-app-backend/./app/util.py", line 21, in wrapper
    raise e
  File "/home/DriveKraft/drivekraft-app-backend/./app/util.py", line 15, in wrapper
    result = func(*args, **kwargs)
  File "/home/DriveKraft/drivekraft-app-backend/./app/util.py", line 43, in wrapper
    return func(*args, **kwargs)
  File "/home/DriveKraft/drivekraft-app-backend/./app/authenticate.py", line 16, in wrapper
    return func(*args, **kwargs)
  File "/home/DriveKraft/drivekraft-app-backend/./app/Routes/sessionRoutes.py", line 47, in fetchSessionRequestFun
    response = sessionService.fetchSessionRequest().__dict__
  File "/home/DriveKraft/drivekraft-app-backend/./app/Services/sessionService.py", line 56, in fetchSessionRequest
    sessionRequest= sessionDao.fetchSessionRequestByUserId(user.id)
  File "/home/DriveKraft/drivekraft-app-backend/./app/Models/DAO/sessionDao.py", line 49, in fetchSessionRequestByUserId
    SessionRequest.sessionRequestStatus=='CREATED',SessionRequest.expired >now)).one()
  File "/usr/local/lib/python3.10/site-packages/sqlalchemy/sql/operators.py", line 360, in __eq__
    return self.operate(eq, other)
  File "/usr/local/lib/python3.10/site-packages/sqlalchemy/orm/attributes.py", line 317, in operate
    return op(self.comparator, *other, **kwargs)
  File "/usr/local/lib/python3.10/site-packages/sqlalchemy/orm/relationships.py", line 1308, in __eq__
    self.property._optimized_compare(
  File "/usr/local/lib/python3.10/site-packages/sqlalchemy/orm/relationships.py", line 1696, in _optimized_compare
    raise sa_exc.ArgumentError(
sqlalchemy.exc.ArgumentError: Mapped instance expected for relationship comparison to object.   Classes, queries and other SQL elements are not accepted in this context; for comparison with a subquery, use SessionRequest.sessionRequestStatus.has(**criteria).
2024-01-18 18:23:28,865 - app - ERROR - Exception on /api/session/request/fetch [GET]
Traceback (most recent call last):
  File "/home/DriveKraft/.local/lib/python3.10/site-packages/flask/app.py", line 2525, in wsgi_app
    response = self.full_dispatch_request()
  File "/home/DriveKraft/.local/lib/python3.10/site-packages/flask/app.py", line 1822, in full_dispatch_request
    rv = self.handle_user_exception(e)
  File "/home/DriveKraft/.local/lib/python3.10/site-packages/flask/app.py", line 1820, in full_dispatch_request
    rv = self.dispatch_request()
  File "/home/DriveKraft/.local/lib/python3.10/site-packages/flask/app.py", line 1796, in dispatch_request
    return self.ensure_sync(self.view_functions[rule.endpoint])(**view_args)
  File "/home/DriveKraft/drivekraft-app-backend/./app/util.py", line 21, in wrapper
    raise e
  File "/home/DriveKraft/drivekraft-app-backend/./app/util.py", line 15, in wrapper
    result = func(*args, **kwargs)
  File "/home/DriveKraft/drivekraft-app-backend/./app/util.py", line 43, in wrapper
    return func(*args, **kwargs)
  File "/home/DriveKraft/drivekraft-app-backend/./app/authenticate.py", line 16, in wrapper
    return func(*args, **kwargs)
  File "/home/DriveKraft/drivekraft-app-backend/./app/Routes/sessionRoutes.py", line 47, in fetchSessionRequestFun
    response = sessionService.fetchSessionRequest().__dict__
  File "/home/DriveKraft/drivekraft-app-backend/./app/Services/sessionService.py", line 56, in fetchSessionRequest
    sessionRequest= sessionDao.fetchSessionRequestByUserId(user.id)
  File "/home/DriveKraft/drivekraft-app-backend/./app/Models/DAO/sessionDao.py", line 49, in fetchSessionRequestByUserId
    SessionRequest.sessionRequestStatus=='CREATED',SessionRequest.expired >now)).one()
  File "/usr/local/lib/python3.10/site-packages/sqlalchemy/sql/operators.py", line 360, in __eq__
    return self.operate(eq, other)
  File "/usr/local/lib/python3.10/site-packages/sqlalchemy/orm/attributes.py", line 317, in operate
    return op(self.comparator, *other, **kwargs)
  File "/usr/local/lib/python3.10/site-packages/sqlalchemy/orm/relationships.py", line 1308, in __eq__
    self.property._optimized_compare(
  File "/usr/local/lib/python3.10/site-packages/sqlalchemy/orm/relationships.py", line 1696, in _optimized_compare
    raise sa_exc.ArgumentError(
sqlalchemy.exc.ArgumentError: Mapped instance expected for relationship comparison to object.   Classes, queries and other SQL elements are not accepted in this context; for comparison with a subquery, use SessionRequest.sessionRequestStatus.has(**criteria).
2024-01-18 18:23:58,880 - app - ERROR - Exception on /api/session/request/fetch [GET]
Traceback (most recent call last):
  File "/home/DriveKraft/.local/lib/python3.10/site-packages/flask/app.py", line 2525, in wsgi_app
    response = self.full_dispatch_request()
  File "/home/DriveKraft/.local/lib/python3.10/site-packages/flask/app.py", line 1822, in full_dispatch_request
    rv = self.handle_user_exception(e)
  File "/home/DriveKraft/.local/lib/python3.10/site-packages/flask/app.py", line 1820, in full_dispatch_request
    rv = self.dispatch_request()
  File "/home/DriveKraft/.local/lib/python3.10/site-packages/flask/app.py", line 1796, in dispatch_request
    return self.ensure_sync(self.view_functions[rule.endpoint])(**view_args)
  File "/home/DriveKraft/drivekraft-app-backend/./app/util.py", line 21, in wrapper
    raise e
  File "/home/DriveKraft/drivekraft-app-backend/./app/util.py", line 15, in wrapper
    result = func(*args, **kwargs)
  File "/home/DriveKraft/drivekraft-app-backend/./app/util.py", line 43, in wrapper
    return func(*args, **kwargs)
  File "/home/DriveKraft/drivekraft-app-backend/./app/authenticate.py", line 16, in wrapper
    return func(*args, **kwargs)
  File "/home/DriveKraft/drivekraft-app-backend/./app/Routes/sessionRoutes.py", line 47, in fetchSessionRequestFun
    response = sessionService.fetchSessionRequest().__dict__
  File "/home/DriveKraft/drivekraft-app-backend/./app/Services/sessionService.py", line 56, in fetchSessionRequest
    sessionRequest= sessionDao.fetchSessionRequestByUserId(user.id)
  File "/home/DriveKraft/drivekraft-app-backend/./app/Models/DAO/sessionDao.py", line 49, in fetchSessionRequestByUserId
    SessionRequest.sessionRequestStatus=='CREATED',SessionRequest.expired >now)).one()
  File "/usr/local/lib/python3.10/site-packages/sqlalchemy/sql/operators.py", line 360, in __eq__
    return self.operate(eq, other)
  File "/usr/local/lib/python3.10/site-packages/sqlalchemy/orm/attributes.py", line 317, in operate
    return op(self.comparator, *other, **kwargs)
  File "/usr/local/lib/python3.10/site-packages/sqlalchemy/orm/relationships.py", line 1308, in __eq__
    self.property._optimized_compare(
  File "/usr/local/lib/python3.10/site-packages/sqlalchemy/orm/relationships.py", line 1696, in _optimized_compare
    raise sa_exc.ArgumentError(
sqlalchemy.exc.ArgumentError: Mapped instance expected for relationship comparison to object.   Classes, queries and other SQL elements are not accepted in this context; for comparison with a subquery, use SessionRequest.sessionRequestStatus.has(**criteria).
2024-01-18 18:24:16,079 - app - ERROR - Exception on /api/session/request/fetch [GET]
Traceback (most recent call last):
  File "/home/DriveKraft/.local/lib/python3.10/site-packages/flask/app.py", line 2525, in wsgi_app
    response = self.full_dispatch_request()
  File "/home/DriveKraft/.local/lib/python3.10/site-packages/flask/app.py", line 1822, in full_dispatch_request
    rv = self.handle_user_exception(e)
  File "/home/DriveKraft/.local/lib/python3.10/site-packages/flask/app.py", line 1820, in full_dispatch_request
    rv = self.dispatch_request()
  File "/home/DriveKraft/.local/lib/python3.10/site-packages/flask/app.py", line 1796, in dispatch_request
    return self.ensure_sync(self.view_functions[rule.endpoint])(**view_args)
  File "/home/DriveKraft/drivekraft-app-backend/./app/util.py", line 21, in wrapper
    raise e
  File "/home/DriveKraft/drivekraft-app-backend/./app/util.py", line 15, in wrapper
    result = func(*args, **kwargs)
  File "/home/DriveKraft/drivekraft-app-backend/./app/util.py", line 43, in wrapper
    return func(*args, **kwargs)
  File "/home/DriveKraft/drivekraft-app-backend/./app/authenticate.py", line 16, in wrapper
    return func(*args, **kwargs)
  File "/home/DriveKraft/drivekraft-app-backend/./app/Routes/sessionRoutes.py", line 47, in fetchSessionRequestFun
    response = sessionService.fetchSessionRequest().__dict__
  File "/home/DriveKraft/drivekraft-app-backend/./app/Services/sessionService.py", line 56, in fetchSessionRequest
    sessionRequest= sessionDao.fetchSessionRequestByUserId(user.id)
  File "/home/DriveKraft/drivekraft-app-backend/./app/Models/DAO/sessionDao.py", line 49, in fetchSessionRequestByUserId
    SessionRequest.sessionRequestStatus=='CREATED',SessionRequest.expired >now)).one()
  File "/usr/local/lib/python3.10/site-packages/sqlalchemy/sql/operators.py", line 360, in __eq__
    return self.operate(eq, other)
  File "/usr/local/lib/python3.10/site-packages/sqlalchemy/orm/attributes.py", line 317, in operate
    return op(self.comparator, *other, **kwargs)
  File "/usr/local/lib/python3.10/site-packages/sqlalchemy/orm/relationships.py", line 1308, in __eq__
    self.property._optimized_compare(
  File "/usr/local/lib/python3.10/site-packages/sqlalchemy/orm/relationships.py", line 1696, in _optimized_compare
    raise sa_exc.ArgumentError(
sqlalchemy.exc.ArgumentError: Mapped instance expected for relationship comparison to object.   Classes, queries and other SQL elements are not accepted in this context; for comparison with a subquery, use SessionRequest.sessionRequestStatus.has(**criteria).
2024-01-18 18:24:47,056 - app - ERROR - Exception on /api/session/request/fetch [GET]
Traceback (most recent call last):
  File "/home/DriveKraft/.local/lib/python3.10/site-packages/flask/app.py", line 2525, in wsgi_app
    response = self.full_dispatch_request()
  File "/home/DriveKraft/.local/lib/python3.10/site-packages/flask/app.py", line 1822, in full_dispatch_request
    rv = self.handle_user_exception(e)
  File "/home/DriveKraft/.local/lib/python3.10/site-packages/flask/app.py", line 1820, in full_dispatch_request
    rv = self.dispatch_request()
  File "/home/DriveKraft/.local/lib/python3.10/site-packages/flask/app.py", line 1796, in dispatch_request
    return self.ensure_sync(self.view_functions[rule.endpoint])(**view_args)
  File "/home/DriveKraft/drivekraft-app-backend/./app/util.py", line 21, in wrapper
    raise e
  File "/home/DriveKraft/drivekraft-app-backend/./app/util.py", line 15, in wrapper
    result = func(*args, **kwargs)
  File "/home/DriveKraft/drivekraft-app-backend/./app/util.py", line 43, in wrapper
    return func(*args, **kwargs)
  File "/home/DriveKraft/drivekraft-app-backend/./app/authenticate.py", line 16, in wrapper
    return func(*args, **kwargs)
  File "/home/DriveKraft/drivekraft-app-backend/./app/Routes/sessionRoutes.py", line 47, in fetchSessionRequestFun
    response = sessionService.fetchSessionRequest().__dict__
  File "/home/DriveKraft/drivekraft-app-backend/./app/Services/sessionService.py", line 56, in fetchSessionRequest
    sessionRequest= sessionDao.fetchSessionRequestByUserId(user.id)
  File "/home/DriveKraft/drivekraft-app-backend/./app/Models/DAO/sessionDao.py", line 49, in fetchSessionRequestByUserId
    SessionRequest.sessionRequestStatus=='CREATED',SessionRequest.expired >now)).one()
  File "/usr/local/lib/python3.10/site-packages/sqlalchemy/sql/operators.py", line 360, in __eq__
    return self.operate(eq, other)
  File "/usr/local/lib/python3.10/site-packages/sqlalchemy/orm/attributes.py", line 317, in operate
    return op(self.comparator, *other, **kwargs)
  File "/usr/local/lib/python3.10/site-packages/sqlalchemy/orm/relationships.py", line 1308, in __eq__
    self.property._optimized_compare(
  File "/usr/local/lib/python3.10/site-packages/sqlalchemy/orm/relationships.py", line 1696, in _optimized_compare
    raise sa_exc.ArgumentError(
sqlalchemy.exc.ArgumentError: Mapped instance expected for relationship comparison to object.   Classes, queries and other SQL elements are not accepted in this context; for comparison with a subquery, use SessionRequest.sessionRequestStatus.has(**criteria).
2024-01-18 18:25:16,149 - app - ERROR - Exception on /api/session/request/fetch [GET]
Traceback (most recent call last):
  File "/home/DriveKraft/.local/lib/python3.10/site-packages/flask/app.py", line 2525, in wsgi_app
    response = self.full_dispatch_request()
  File "/home/DriveKraft/.local/lib/python3.10/site-packages/flask/app.py", line 1822, in full_dispatch_request
    rv = self.handle_user_exception(e)
  File "/home/DriveKraft/.local/lib/python3.10/site-packages/flask/app.py", line 1820, in full_dispatch_request
    rv = self.dispatch_request()
  File "/home/DriveKraft/.local/lib/python3.10/site-packages/flask/app.py", line 1796, in dispatch_request
    return self.ensure_sync(self.view_functions[rule.endpoint])(**view_args)
  File "/home/DriveKraft/drivekraft-app-backend/./app/util.py", line 21, in wrapper
    raise e
  File "/home/DriveKraft/drivekraft-app-backend/./app/util.py", line 15, in wrapper
    result = func(*args, **kwargs)
  File "/home/DriveKraft/drivekraft-app-backend/./app/util.py", line 43, in wrapper
    return func(*args, **kwargs)
  File "/home/DriveKraft/drivekraft-app-backend/./app/authenticate.py", line 16, in wrapper
    return func(*args, **kwargs)
  File "/home/DriveKraft/drivekraft-app-backend/./app/Routes/sessionRoutes.py", line 47, in fetchSessionRequestFun
    response = sessionService.fetchSessionRequest().__dict__
  File "/home/DriveKraft/drivekraft-app-backend/./app/Services/sessionService.py", line 56, in fetchSessionRequest
    sessionRequest= sessionDao.fetchSessionRequestByUserId(user.id)
  File "/home/DriveKraft/drivekraft-app-backend/./app/Models/DAO/sessionDao.py", line 49, in fetchSessionRequestByUserId
    SessionRequest.sessionRequestStatus=='CREATED',SessionRequest.expired >now)).one()
  File "/usr/local/lib/python3.10/site-packages/sqlalchemy/sql/operators.py", line 360, in __eq__
    return self.operate(eq, other)
  File "/usr/local/lib/python3.10/site-packages/sqlalchemy/orm/attributes.py", line 317, in operate
    return op(self.comparator, *other, **kwargs)
  File "/usr/local/lib/python3.10/site-packages/sqlalchemy/orm/relationships.py", line 1308, in __eq__
    self.property._optimized_compare(
  File "/usr/local/lib/python3.10/site-packages/sqlalchemy/orm/relationships.py", line 1696, in _optimized_compare
    raise sa_exc.ArgumentError(
sqlalchemy.exc.ArgumentError: Mapped instance expected for relationship comparison to object.   Classes, queries and other SQL elements are not accepted in this context; for comparison with a subquery, use SessionRequest.sessionRequestStatus.has(**criteria).
2024-01-18 18:32:20,629 - app - ERROR - Exception on /api/check/user/bal [GET]
Traceback (most recent call last):
  File "/usr/local/lib/python3.10/site-packages/sqlalchemy/engine/base.py", line 3280, in _wrap_pool_connect
    return fn()
  File "/usr/local/lib/python3.10/site-packages/sqlalchemy/pool/base.py", line 310, in connect
    return _ConnectionFairy._checkout(self)
  File "/usr/local/lib/python3.10/site-packages/sqlalchemy/pool/base.py", line 901, in _checkout
    result = pool._dialect.do_ping(fairy.dbapi_connection)
  File "/usr/local/lib/python3.10/site-packages/sqlalchemy/dialects/mysql/mysqldb.py", line 183, in do_ping
    dbapi_connection.ping(False)
MySQLdb._exceptions.OperationalError: (4031, 'The client was disconnected by the server because of inactivity. See wait_timeout and interactive_timeout for configuring this behavior.')

The above exception was the direct cause of the following exception:

Traceback (most recent call last):
  File "/home/DriveKraft/.local/lib/python3.10/site-packages/flask/app.py", line 2525, in wsgi_app
    response = self.full_dispatch_request()
  File "/home/DriveKraft/.local/lib/python3.10/site-packages/flask/app.py", line 1822, in full_dispatch_request
    rv = self.handle_user_exception(e)
  File "/home/DriveKraft/.local/lib/python3.10/site-packages/flask/app.py", line 1820, in full_dispatch_request
    rv = self.dispatch_request()
  File "/home/DriveKraft/.local/lib/python3.10/site-packages/flask/app.py", line 1796, in dispatch_request
    return self.ensure_sync(self.view_functions[rule.endpoint])(**view_args)
  File "/home/DriveKraft/drivekraft-app-backend/./app/util.py", line 43, in wrapper
    return func(*args, **kwargs)
  File "/home/DriveKraft/drivekraft-app-backend/./app/util.py", line 21, in wrapper
    raise e
  File "/home/DriveKraft/drivekraft-app-backend/./app/util.py", line 15, in wrapper
    result = func(*args, **kwargs)
  File "/home/DriveKraft/drivekraft-app-backend/./app/authenticate.py", line 16, in wrapper
    return func(*args, **kwargs)
  File "/home/DriveKraft/drivekraft-app-backend/./app/Routes/userRoutes.py", line 41, in fetchUserBalanceDetails
    response = userService.getUserBalance().__dict__
  File "/home/DriveKraft/drivekraft-app-backend/./app/Services/userService.py", line 59, in getUserBalance
    user = getUserDetails()
  File "/home/DriveKraft/drivekraft-app-backend/./app/Services/userService.py", line 100, in getUserDetails
    user = getUserByToken(g.tokenValue)
  File "/home/DriveKraft/drivekraft-app-backend/./app/Services/userService.py", line 96, in getUserByToken
    return userDao.getUserById(token.userId)
  File "/home/DriveKraft/drivekraft-app-backend/./app/Models/DAO/userDao.py", line 53, in getUserById
    user = session.query(User).filter_by(id=userId).one()
  File "/usr/local/lib/python3.10/site-packages/sqlalchemy/orm/query.py", line 2865, in one
    return self._iter().one()
  File "/usr/local/lib/python3.10/site-packages/sqlalchemy/orm/query.py", line 2903, in _iter
    result = self.session.execute(
  File "/usr/local/lib/python3.10/site-packages/sqlalchemy/orm/session.py", line 1695, in execute
    conn = self._connection_for_bind(bind)
  File "/usr/local/lib/python3.10/site-packages/sqlalchemy/orm/session.py", line 1536, in _connection_for_bind
    return self._transaction._connection_for_bind(
  File "/usr/local/lib/python3.10/site-packages/sqlalchemy/orm/session.py", line 747, in _connection_for_bind
    conn = bind.connect()
  File "/usr/local/lib/python3.10/site-packages/sqlalchemy/engine/base.py", line 3234, in connect
    return self._connection_cls(self, close_with_result=close_with_result)
  File "/usr/local/lib/python3.10/site-packages/sqlalchemy/engine/base.py", line 96, in __init__
    else engine.raw_connection()
  File "/usr/local/lib/python3.10/site-packages/sqlalchemy/engine/base.py", line 3313, in raw_connection
    return self._wrap_pool_connect(self.pool.connect, _connection)
  File "/usr/local/lib/python3.10/site-packages/sqlalchemy/engine/base.py", line 3283, in _wrap_pool_connect
    Connection._handle_dbapi_exception_noconnection(
  File "/usr/local/lib/python3.10/site-packages/sqlalchemy/engine/base.py", line 2117, in _handle_dbapi_exception_noconnection
    util.raise_(
  File "/usr/local/lib/python3.10/site-packages/sqlalchemy/util/compat.py", line 207, in raise_
    raise exception
  File "/usr/local/lib/python3.10/site-packages/sqlalchemy/engine/base.py", line 3280, in _wrap_pool_connect
    return fn()
  File "/usr/local/lib/python3.10/site-packages/sqlalchemy/pool/base.py", line 310, in connect
    return _ConnectionFairy._checkout(self)
  File "/usr/local/lib/python3.10/site-packages/sqlalchemy/pool/base.py", line 901, in _checkout
    result = pool._dialect.do_ping(fairy.dbapi_connection)
  File "/usr/local/lib/python3.10/site-packages/sqlalchemy/dialects/mysql/mysqldb.py", line 183, in do_ping
    dbapi_connection.ping(False)
sqlalchemy.exc.OperationalError: (MySQLdb._exceptions.OperationalError) (4031, 'The client was disconnected by the server because of inactivity. See wait_timeout and interactive_timeout for configuring this behavior.')
(Background on this error at: https://sqlalche.me/e/14/e3q8)
2024-01-18 21:33:20,835 - app - ERROR - Exception on /api/session/request/fetch [GET]
Traceback (most recent call last):
  File "/home/DriveKraft/.local/lib/python3.10/site-packages/flask/app.py", line 2525, in wsgi_app
    response = self.full_dispatch_request()
  File "/home/DriveKraft/.local/lib/python3.10/site-packages/flask/app.py", line 1822, in full_dispatch_request
    rv = self.handle_user_exception(e)
  File "/home/DriveKraft/.local/lib/python3.10/site-packages/flask/app.py", line 1820, in full_dispatch_request
    rv = self.dispatch_request()
  File "/home/DriveKraft/.local/lib/python3.10/site-packages/flask/app.py", line 1796, in dispatch_request
    return self.ensure_sync(self.view_functions[rule.endpoint])(**view_args)
  File "/home/DriveKraft/drivekraft-app-backend/./app/util.py", line 21, in wrapper
    raise e
  File "/home/DriveKraft/drivekraft-app-backend/./app/util.py", line 15, in wrapper
    result = func(*args, **kwargs)
  File "/home/DriveKraft/drivekraft-app-backend/./app/util.py", line 43, in wrapper
    return func(*args, **kwargs)
  File "/home/DriveKraft/drivekraft-app-backend/./app/authenticate.py", line 16, in wrapper
    return func(*args, **kwargs)
  File "/home/DriveKraft/drivekraft-app-backend/./app/Routes/sessionRoutes.py", line 47, in fetchSessionRequestFun
    response = sessionService.fetchSessionRequest().__dict__
  File "/home/DriveKraft/drivekraft-app-backend/./app/Services/sessionService.py", line 56, in fetchSessionRequest
    sessionRequest= sessionDao.fetchSessionRequestByUserId(user.id)
  File "/home/DriveKraft/drivekraft-app-backend/./app/Models/DAO/sessionDao.py", line 49, in fetchSessionRequestByUserId
    SessionRequest.sessionRequestStatus=='CREATED',SessionRequest.expired >now)).one()
  File "/usr/local/lib/python3.10/site-packages/sqlalchemy/sql/operators.py", line 360, in __eq__
    return self.operate(eq, other)
  File "/usr/local/lib/python3.10/site-packages/sqlalchemy/orm/attributes.py", line 317, in operate
    return op(self.comparator, *other, **kwargs)
  File "/usr/local/lib/python3.10/site-packages/sqlalchemy/orm/relationships.py", line 1308, in __eq__
    self.property._optimized_compare(
  File "/usr/local/lib/python3.10/site-packages/sqlalchemy/orm/relationships.py", line 1696, in _optimized_compare
    raise sa_exc.ArgumentError(
sqlalchemy.exc.ArgumentError: Mapped instance expected for relationship comparison to object.   Classes, queries and other SQL elements are not accepted in this context; for comparison with a subquery, use SessionRequest.sessionRequestStatus.has(**criteria).
2024-01-18 21:33:21,258 - app - ERROR - Exception on /api/session/request/fetch [GET]
Traceback (most recent call last):
  File "/home/DriveKraft/.local/lib/python3.10/site-packages/flask/app.py", line 2525, in wsgi_app
    response = self.full_dispatch_request()
  File "/home/DriveKraft/.local/lib/python3.10/site-packages/flask/app.py", line 1822, in full_dispatch_request
    rv = self.handle_user_exception(e)
  File "/home/DriveKraft/.local/lib/python3.10/site-packages/flask/app.py", line 1820, in full_dispatch_request
    rv = self.dispatch_request()
  File "/home/DriveKraft/.local/lib/python3.10/site-packages/flask/app.py", line 1796, in dispatch_request
    return self.ensure_sync(self.view_functions[rule.endpoint])(**view_args)
  File "/home/DriveKraft/drivekraft-app-backend/./app/util.py", line 21, in wrapper
    raise e
  File "/home/DriveKraft/drivekraft-app-backend/./app/util.py", line 15, in wrapper
    result = func(*args, **kwargs)
  File "/home/DriveKraft/drivekraft-app-backend/./app/util.py", line 43, in wrapper
    return func(*args, **kwargs)
  File "/home/DriveKraft/drivekraft-app-backend/./app/authenticate.py", line 16, in wrapper
    return func(*args, **kwargs)
  File "/home/DriveKraft/drivekraft-app-backend/./app/Routes/sessionRoutes.py", line 47, in fetchSessionRequestFun
    response = sessionService.fetchSessionRequest().__dict__
  File "/home/DriveKraft/drivekraft-app-backend/./app/Services/sessionService.py", line 56, in fetchSessionRequest
    sessionRequest= sessionDao.fetchSessionRequestByUserId(user.id)
  File "/home/DriveKraft/drivekraft-app-backend/./app/Models/DAO/sessionDao.py", line 49, in fetchSessionRequestByUserId
    SessionRequest.sessionRequestStatus=='CREATED',SessionRequest.expired >now)).one()
  File "/usr/local/lib/python3.10/site-packages/sqlalchemy/sql/operators.py", line 360, in __eq__
    return self.operate(eq, other)
  File "/usr/local/lib/python3.10/site-packages/sqlalchemy/orm/attributes.py", line 317, in operate
    return op(self.comparator, *other, **kwargs)
  File "/usr/local/lib/python3.10/site-packages/sqlalchemy/orm/relationships.py", line 1308, in __eq__
    self.property._optimized_compare(
  File "/usr/local/lib/python3.10/site-packages/sqlalchemy/orm/relationships.py", line 1696, in _optimized_compare
    raise sa_exc.ArgumentError(
sqlalchemy.exc.ArgumentError: Mapped instance expected for relationship comparison to object.   Classes, queries and other SQL elements are not accepted in this context; for comparison with a subquery, use SessionRequest.sessionRequestStatus.has(**criteria).
