2024-01-13 00:28:52,122 - app - ERROR - Exception on /api/login-send-otp [POST]
Traceback (most recent call last):
  File "/Users/virender/Desktop/DriveKraft-Backend/venv/lib/python3.11/site-packages/flask/app.py", line 1455, in wsgi_app
    response = self.full_dispatch_request()
               ^^^^^^^^^^^^^^^^^^^^^^^^^^^^
  File "/Users/virender/Desktop/DriveKraft-Backend/venv/lib/python3.11/site-packages/flask/app.py", line 869, in full_dispatch_request
    rv = self.handle_user_exception(e)
         ^^^^^^^^^^^^^^^^^^^^^^^^^^^^^
  File "/Users/virender/Desktop/DriveKraft-Backend/venv/lib/python3.11/site-packages/flask/app.py", line 867, in full_dispatch_request
    rv = self.dispatch_request()
         ^^^^^^^^^^^^^^^^^^^^^^^
  File "/Users/virender/Desktop/DriveKraft-Backend/venv/lib/python3.11/site-packages/flask/app.py", line 852, in dispatch_request
    return self.ensure_sync(self.view_functions[rule.endpoint])(**view_args)
           ^^^^^^^^^^^^^^^^^^^^^^^^^^^^^^^^^^^^^^^^^^^^^^^^^^^^^^^^^^^^^^^^^
  File "/Users/virender/Desktop/DriveKraft-Backend/app/util.py", line 20, in wrapper
    raise e
  File "/Users/virender/Desktop/DriveKraft-Backend/app/util.py", line 14, in wrapper
    result = func(*args, **kwargs)
             ^^^^^^^^^^^^^^^^^^^^^
  File "/Users/virender/Desktop/DriveKraft-Backend/app/util.py", line 39, in wrapper
    return func(*args, **kwargs)
           ^^^^^^^^^^^^^^^^^^^^^
  File "/Users/virender/Desktop/DriveKraft-Backend/app/Routes/otpRoutes.py", line 15, in generateNewOtp
    otpRequest = otpGenerateRequest.otpGenerateRequest(**request.json_data)
                 ^^^^^^^^^^^^^^^^^^^^^^^^^^^^^^^^^^^^^^^^^^^^^^^^^^^^^^^^^^
TypeError: app.Contract.Request.otpGenerateRequest.otpGenerateRequest() argument after ** must be a mapping, not NoneType
2024-01-13 01:35:03,040 - app - ERROR - Exception on /api/psychologist/create [POST]
Traceback (most recent call last):
  File "/Users/virender/Desktop/DriveKraft-Backend/venv/lib/python3.11/site-packages/flask/app.py", line 1455, in wsgi_app
    response = self.full_dispatch_request()
               ^^^^^^^^^^^^^^^^^^^^^^^^^^^^
  File "/Users/virender/Desktop/DriveKraft-Backend/venv/lib/python3.11/site-packages/flask/app.py", line 869, in full_dispatch_request
    rv = self.handle_user_exception(e)
         ^^^^^^^^^^^^^^^^^^^^^^^^^^^^^
  File "/Users/virender/Desktop/DriveKraft-Backend/venv/lib/python3.11/site-packages/flask/app.py", line 867, in full_dispatch_request
    rv = self.dispatch_request()
         ^^^^^^^^^^^^^^^^^^^^^^^
  File "/Users/virender/Desktop/DriveKraft-Backend/venv/lib/python3.11/site-packages/flask/app.py", line 852, in dispatch_request
    return self.ensure_sync(self.view_functions[rule.endpoint])(**view_args)
           ^^^^^^^^^^^^^^^^^^^^^^^^^^^^^^^^^^^^^^^^^^^^^^^^^^^^^^^^^^^^^^^^^
  File "/Users/virender/Desktop/DriveKraft-Backend/app/util.py", line 21, in wrapper
    raise e
  File "/Users/virender/Desktop/DriveKraft-Backend/app/util.py", line 15, in wrapper
    result = func(*args, **kwargs)
             ^^^^^^^^^^^^^^^^^^^^^
  File "/Users/virender/Desktop/DriveKraft-Backend/app/util.py", line 40, in wrapper
    return func(*args, **kwargs)
           ^^^^^^^^^^^^^^^^^^^^^
  File "/Users/virender/Desktop/DriveKraft-Backend/app/Routes/psychologistRoutes.py", line 41, in createPsychologist
    requestData = createPsychologistRequest.createPsychologistRequest(**request.json_data)
                  ^^^^^^^^^^^^^^^^^^^^^^^^^^^^^^^^^^^^^^^^^^^^^^^^^^^^^^^^^^^^^^^^^^^^^^^^
TypeError: createPsychologistRequest.__init__() got an unexpected keyword argument 'education  '
2024-01-13 01:35:19,723 - app - ERROR - Exception on /api/psychologist/create [POST]
Traceback (most recent call last):
  File "/Users/virender/Desktop/DriveKraft-Backend/venv/lib/python3.11/site-packages/flask/app.py", line 1455, in wsgi_app
    response = self.full_dispatch_request()
               ^^^^^^^^^^^^^^^^^^^^^^^^^^^^
  File "/Users/virender/Desktop/DriveKraft-Backend/venv/lib/python3.11/site-packages/flask/app.py", line 869, in full_dispatch_request
    rv = self.handle_user_exception(e)
         ^^^^^^^^^^^^^^^^^^^^^^^^^^^^^
  File "/Users/virender/Desktop/DriveKraft-Backend/venv/lib/python3.11/site-packages/flask/app.py", line 867, in full_dispatch_request
    rv = self.dispatch_request()
         ^^^^^^^^^^^^^^^^^^^^^^^
  File "/Users/virender/Desktop/DriveKraft-Backend/venv/lib/python3.11/site-packages/flask/app.py", line 852, in dispatch_request
    return self.ensure_sync(self.view_functions[rule.endpoint])(**view_args)
           ^^^^^^^^^^^^^^^^^^^^^^^^^^^^^^^^^^^^^^^^^^^^^^^^^^^^^^^^^^^^^^^^^
  File "/Users/virender/Desktop/DriveKraft-Backend/app/util.py", line 21, in wrapper
    raise e
  File "/Users/virender/Desktop/DriveKraft-Backend/app/util.py", line 15, in wrapper
    result = func(*args, **kwargs)
             ^^^^^^^^^^^^^^^^^^^^^
  File "/Users/virender/Desktop/DriveKraft-Backend/app/util.py", line 40, in wrapper
    return func(*args, **kwargs)
           ^^^^^^^^^^^^^^^^^^^^^
  File "/Users/virender/Desktop/DriveKraft-Backend/app/Routes/psychologistRoutes.py", line 42, in createPsychologist
    response = psychologistService.createPsychologist(requestData).__dict__
               ^^^^^^^^^^^^^^^^^^^^^^^^^^^^^^^^^^^^^^^^^^^^^^^^^^^
  File "/Users/virender/Desktop/DriveKraft-Backend/app/Services/psychologistService.py", line 67, in createPsychologist
    result = psychologistDao.createPsychologist(psychologist, psychologistData)
             ^^^^^^^^^^^^^^^^^^^^^^^^^^^^^^^^^^^^^^^^^^^^^^^^^^^^^^^^^^^^^^^^^^
  File "/Users/virender/Desktop/DriveKraft-Backend/app/Models/DAO/psychologistDao.py", line 52, in createPsychologist
    return {'id':psy.id,'dataId':psyData.id}
                 ^^^^^^
AttributeError: 'NoneType' object has no attribute 'id'
2024-01-13 01:36:57,026 - app - ERROR - Exception on /api/psychologist/create [POST]
Traceback (most recent call last):
  File "/Users/virender/Desktop/DriveKraft-Backend/venv/lib/python3.11/site-packages/flask/app.py", line 1455, in wsgi_app
    response = self.full_dispatch_request()
               ^^^^^^^^^^^^^^^^^^^^^^^^^^^^
  File "/Users/virender/Desktop/DriveKraft-Backend/venv/lib/python3.11/site-packages/flask/app.py", line 869, in full_dispatch_request
    rv = self.handle_user_exception(e)
         ^^^^^^^^^^^^^^^^^^^^^^^^^^^^^
  File "/Users/virender/Desktop/DriveKraft-Backend/venv/lib/python3.11/site-packages/flask/app.py", line 867, in full_dispatch_request
    rv = self.dispatch_request()
         ^^^^^^^^^^^^^^^^^^^^^^^
  File "/Users/virender/Desktop/DriveKraft-Backend/venv/lib/python3.11/site-packages/flask/app.py", line 852, in dispatch_request
    return self.ensure_sync(self.view_functions[rule.endpoint])(**view_args)
           ^^^^^^^^^^^^^^^^^^^^^^^^^^^^^^^^^^^^^^^^^^^^^^^^^^^^^^^^^^^^^^^^^
  File "/Users/virender/Desktop/DriveKraft-Backend/app/util.py", line 21, in wrapper
    raise e
  File "/Users/virender/Desktop/DriveKraft-Backend/app/util.py", line 15, in wrapper
    result = func(*args, **kwargs)
             ^^^^^^^^^^^^^^^^^^^^^
  File "/Users/virender/Desktop/DriveKraft-Backend/app/util.py", line 40, in wrapper
    return func(*args, **kwargs)
           ^^^^^^^^^^^^^^^^^^^^^
  File "/Users/virender/Desktop/DriveKraft-Backend/app/Routes/psychologistRoutes.py", line 42, in createPsychologist
    response = psychologistService.createPsychologist(requestData).__dict__
               ^^^^^^^^^^^^^^^^^^^^^^^^^^^^^^^^^^^^^^^^^^^^^^^^^^^
  File "/Users/virender/Desktop/DriveKraft-Backend/app/Services/psychologistService.py", line 67, in createPsychologist
    result = psychologistDao.createPsychologist(psychologist, psychologistData)
             ^^^^^^^^^^^^^^^^^^^^^^^^^^^^^^^^^^^^^^^^^^^^^^^^^^^^^^^^^^^^^^^^^^
  File "/Users/virender/Desktop/DriveKraft-Backend/app/Models/DAO/psychologistDao.py", line 54, in createPsychologist
    return {'id':psy.id,'dataId':psyData.id}
                 ^^^^^^
AttributeError: 'NoneType' object has no attribute 'id'
2024-01-13 01:37:03,269 - app - ERROR - Exception on /api/psychologist/create [POST]
Traceback (most recent call last):
  File "/Users/virender/Desktop/DriveKraft-Backend/venv/lib/python3.11/site-packages/flask/app.py", line 1455, in wsgi_app
    response = self.full_dispatch_request()
               ^^^^^^^^^^^^^^^^^^^^^^^^^^^^
  File "/Users/virender/Desktop/DriveKraft-Backend/venv/lib/python3.11/site-packages/flask/app.py", line 869, in full_dispatch_request
    rv = self.handle_user_exception(e)
         ^^^^^^^^^^^^^^^^^^^^^^^^^^^^^
  File "/Users/virender/Desktop/DriveKraft-Backend/venv/lib/python3.11/site-packages/flask/app.py", line 867, in full_dispatch_request
    rv = self.dispatch_request()
         ^^^^^^^^^^^^^^^^^^^^^^^
  File "/Users/virender/Desktop/DriveKraft-Backend/venv/lib/python3.11/site-packages/flask/app.py", line 852, in dispatch_request
    return self.ensure_sync(self.view_functions[rule.endpoint])(**view_args)
           ^^^^^^^^^^^^^^^^^^^^^^^^^^^^^^^^^^^^^^^^^^^^^^^^^^^^^^^^^^^^^^^^^
  File "/Users/virender/Desktop/DriveKraft-Backend/app/util.py", line 21, in wrapper
    raise e
  File "/Users/virender/Desktop/DriveKraft-Backend/app/util.py", line 15, in wrapper
    result = func(*args, **kwargs)
             ^^^^^^^^^^^^^^^^^^^^^
  File "/Users/virender/Desktop/DriveKraft-Backend/app/util.py", line 40, in wrapper
    return func(*args, **kwargs)
           ^^^^^^^^^^^^^^^^^^^^^
  File "/Users/virender/Desktop/DriveKraft-Backend/app/Routes/psychologistRoutes.py", line 42, in createPsychologist
    response = psychologistService.createPsychologist(requestData).__dict__
               ^^^^^^^^^^^^^^^^^^^^^^^^^^^^^^^^^^^^^^^^^^^^^^^^^^^
  File "/Users/virender/Desktop/DriveKraft-Backend/app/Services/psychologistService.py", line 67, in createPsychologist
    result = psychologistDao.createPsychologist(psychologist, psychologistData)
             ^^^^^^^^^^^^^^^^^^^^^^^^^^^^^^^^^^^^^^^^^^^^^^^^^^^^^^^^^^^^^^^^^^
  File "/Users/virender/Desktop/DriveKraft-Backend/app/Models/DAO/psychologistDao.py", line 54, in createPsychologist
    return {'id':psy.id,'dataId':psyData.id}
                 ^^^^^^
AttributeError: 'NoneType' object has no attribute 'id'
2024-01-13 01:44:11,113 - app - ERROR - Exception on /api/psychologist/create [POST]
Traceback (most recent call last):
  File "/Users/virender/Desktop/DriveKraft-Backend/venv/lib/python3.11/site-packages/flask/app.py", line 1455, in wsgi_app
    response = self.full_dispatch_request()
               ^^^^^^^^^^^^^^^^^^^^^^^^^^^^
  File "/Users/virender/Desktop/DriveKraft-Backend/venv/lib/python3.11/site-packages/flask/app.py", line 869, in full_dispatch_request
    rv = self.handle_user_exception(e)
         ^^^^^^^^^^^^^^^^^^^^^^^^^^^^^
  File "/Users/virender/Desktop/DriveKraft-Backend/venv/lib/python3.11/site-packages/flask/app.py", line 867, in full_dispatch_request
    rv = self.dispatch_request()
         ^^^^^^^^^^^^^^^^^^^^^^^
  File "/Users/virender/Desktop/DriveKraft-Backend/venv/lib/python3.11/site-packages/flask/app.py", line 852, in dispatch_request
    return self.ensure_sync(self.view_functions[rule.endpoint])(**view_args)
           ^^^^^^^^^^^^^^^^^^^^^^^^^^^^^^^^^^^^^^^^^^^^^^^^^^^^^^^^^^^^^^^^^
  File "/Users/virender/Desktop/DriveKraft-Backend/app/util.py", line 21, in wrapper
    raise e
  File "/Users/virender/Desktop/DriveKraft-Backend/app/util.py", line 15, in wrapper
    result = func(*args, **kwargs)
             ^^^^^^^^^^^^^^^^^^^^^
  File "/Users/virender/Desktop/DriveKraft-Backend/app/util.py", line 40, in wrapper
    return func(*args, **kwargs)
           ^^^^^^^^^^^^^^^^^^^^^
  File "/Users/virender/Desktop/DriveKraft-Backend/app/Routes/psychologistRoutes.py", line 42, in createPsychologist
    response = psychologistService.createPsychologist(requestData).__dict__
               ^^^^^^^^^^^^^^^^^^^^^^^^^^^^^^^^^^^^^^^^^^^^^^^^^^^
  File "/Users/virender/Desktop/DriveKraft-Backend/app/Services/psychologistService.py", line 67, in createPsychologist
    result = psychologistDao.createPsychologist(psychologist)
             ^^^^^^^^^^^^^^^^^^^^^^^^^^^^^^^^^^^^^^^^^^^^^^^^
  File "/Users/virender/Desktop/DriveKraft-Backend/app/Models/DAO/psychologistDao.py", line 54, in createPsychologist
    return psy.id
           ^^^^^^
AttributeError: 'NoneType' object has no attribute 'id'
2024-01-12 21:21:36,590 - app - ERROR - Exception on /api/login-send-otp [POST]
Traceback (most recent call last):
  File "/home/DriveKraft/.local/lib/python3.10/site-packages/flask/app.py", line 2525, in wsgi_app
    response = self.full_dispatch_request()
  File "/home/DriveKraft/.local/lib/python3.10/site-packages/flask/app.py", line 1822, in full_dispatch_request
    rv = self.handle_user_exception(e)
  File "/home/DriveKraft/.local/lib/python3.10/site-packages/flask/app.py", line 1820, in full_dispatch_request
    rv = self.dispatch_request()
  File "/home/DriveKraft/.local/lib/python3.10/site-packages/flask/app.py", line 1796, in dispatch_request
    return self.ensure_sync(self.view_functions[rule.endpoint])(**view_args)
  File "/home/DriveKraft/drivekraft-app-backend/./app/util.py", line 21, in wrapper
    raise e
  File "/home/DriveKraft/drivekraft-app-backend/./app/util.py", line 15, in wrapper
    result = func(*args, **kwargs)
  File "/home/DriveKraft/drivekraft-app-backend/./app/util.py", line 43, in wrapper
    return func(*args, **kwargs)
  File "/home/DriveKraft/drivekraft-app-backend/./app/Routes/otpRoutes.py", line 17, in generateNewOtp
    response = otpGenerateService.generateOtp(otpRequest).__dict__
  File "/home/DriveKraft/drivekraft-app-backend/./app/Services/otpGenerateService.py", line 22, in generateOtp
    user = userService.getUserByContact(contactNumber=request.mobile)
  File "/home/DriveKraft/drivekraft-app-backend/./app/Services/userService.py", line 84, in getUserByContact
    return userDao.getUserByContact(contactNumber)
  File "/home/DriveKraft/drivekraft-app-backend/./app/Models/DAO/userDao.py", line 35, in getUserByContact
    user = session.query(User).filter_by(contactNumber=contactNumber).one()
  File "/usr/local/lib/python3.10/site-packages/sqlalchemy/orm/query.py", line 2865, in one
    return self._iter().one()
  File "/usr/local/lib/python3.10/site-packages/sqlalchemy/engine/result.py", line 1417, in one
    return self._only_one_row(
  File "/usr/local/lib/python3.10/site-packages/sqlalchemy/engine/result.py", line 614, in _only_one_row
    raise exc.MultipleResultsFound(
sqlalchemy.exc.MultipleResultsFound: Multiple rows were found when exactly one was required
2024-01-12 21:33:57,937 - app - ERROR - Exception on /api/login-send-otp [POST]
Traceback (most recent call last):
  File "/usr/local/lib/python3.10/site-packages/sqlalchemy/engine/base.py", line 1819, in _execute_context
    self.dialect.do_execute(
  File "/usr/local/lib/python3.10/site-packages/sqlalchemy/engine/default.py", line 732, in do_execute
    cursor.execute(statement, parameters)
  File "/usr/local/lib/python3.10/site-packages/MySQLdb/cursors.py", line 206, in execute
    res = self._query(query)
  File "/usr/local/lib/python3.10/site-packages/MySQLdb/cursors.py", line 319, in _query
    db.query(q)
  File "/usr/local/lib/python3.10/site-packages/MySQLdb/connections.py", line 254, in query
    _mysql.connection.query(self, query)
MySQLdb._exceptions.OperationalError: (4031, 'The client was disconnected by the server because of inactivity. See wait_timeout and interactive_timeout for configuring this behavior.')

The above exception was the direct cause of the following exception:

Traceback (most recent call last):
  File "/home/DriveKraft/drivekraft-app-backend/./app/util.py", line 15, in wrapper
    result = func(*args, **kwargs)
  File "/home/DriveKraft/drivekraft-app-backend/./app/util.py", line 43, in wrapper
    return func(*args, **kwargs)
  File "/home/DriveKraft/drivekraft-app-backend/./app/Routes/otpRoutes.py", line 17, in generateNewOtp
    response = otpGenerateService.generateOtp(otpRequest).__dict__
  File "/home/DriveKraft/drivekraft-app-backend/./app/Services/otpGenerateService.py", line 22, in generateOtp
    user = userService.getUserByContact(contactNumber=request.mobile)
  File "/home/DriveKraft/drivekraft-app-backend/./app/Services/userService.py", line 84, in getUserByContact
    return userDao.getUserByContact(contactNumber)
  File "/home/DriveKraft/drivekraft-app-backend/./app/Models/DAO/userDao.py", line 35, in getUserByContact
    user = session.query(User).filter_by(contactNumber=contactNumber).one()
  File "/usr/local/lib/python3.10/site-packages/sqlalchemy/orm/query.py", line 2865, in one
    return self._iter().one()
  File "/usr/local/lib/python3.10/site-packages/sqlalchemy/orm/query.py", line 2903, in _iter
    result = self.session.execute(
  File "/usr/local/lib/python3.10/site-packages/sqlalchemy/orm/session.py", line 1696, in execute
    result = conn._execute_20(statement, params or {}, execution_options)
  File "/usr/local/lib/python3.10/site-packages/sqlalchemy/engine/base.py", line 1631, in _execute_20
    return meth(self, args_10style, kwargs_10style, execution_options)
  File "/usr/local/lib/python3.10/site-packages/sqlalchemy/sql/elements.py", line 325, in _execute_on_connection
    return connection._execute_clauseelement(
  File "/usr/local/lib/python3.10/site-packages/sqlalchemy/engine/base.py", line 1498, in _execute_clauseelement
    ret = self._execute_context(
  File "/usr/local/lib/python3.10/site-packages/sqlalchemy/engine/base.py", line 1862, in _execute_context
    self._handle_dbapi_exception(
  File "/usr/local/lib/python3.10/site-packages/sqlalchemy/engine/base.py", line 2043, in _handle_dbapi_exception
    util.raise_(
  File "/usr/local/lib/python3.10/site-packages/sqlalchemy/util/compat.py", line 207, in raise_
    raise exception
  File "/usr/local/lib/python3.10/site-packages/sqlalchemy/engine/base.py", line 1819, in _execute_context
    self.dialect.do_execute(
  File "/usr/local/lib/python3.10/site-packages/sqlalchemy/engine/default.py", line 732, in do_execute
    cursor.execute(statement, parameters)
  File "/usr/local/lib/python3.10/site-packages/MySQLdb/cursors.py", line 206, in execute
    res = self._query(query)
  File "/usr/local/lib/python3.10/site-packages/MySQLdb/cursors.py", line 319, in _query
    db.query(q)
  File "/usr/local/lib/python3.10/site-packages/MySQLdb/connections.py", line 254, in query
    _mysql.connection.query(self, query)
sqlalchemy.exc.OperationalError: (MySQLdb._exceptions.OperationalError) (4031, 'The client was disconnected by the server because of inactivity. See wait_timeout and interactive_timeout for configuring this behavior.')
[SQL: SELECT user.id AS user_id, user.name AS user_name, user.`contactNumber` AS `user_contactNumber`, user.username AS user_username, user.created AS user_created, user.updated AS user_updated, user.`firebaseId` AS `user_firebaseId`, user.`firebaseName` AS `user_firebaseName`, user.`firebaseEmail` AS `user_firebaseEmail`, user.`firebasePassword` AS `user_firebasePassword`, user.`roleId` AS `user_roleId`, user.balance AS user_balance, user.`isBlocked` AS `user_isBlocked` 
FROM user 
WHERE user.`contactNumber` = %s]
[parameters: ('919812000194',)]
(Background on this error at: https://sqlalche.me/e/14/e3q8)

During handling of the above exception, another exception occurred:

Traceback (most recent call last):
  File "/usr/local/lib/python3.10/site-packages/sqlalchemy/engine/base.py", line 983, in _rollback_impl
    self.engine.dialect.do_rollback(self.connection)
  File "/usr/local/lib/python3.10/site-packages/sqlalchemy/engine/default.py", line 682, in do_rollback
    dbapi_connection.rollback()
MySQLdb._exceptions.InterfaceError: (0, '')

The above exception was the direct cause of the following exception:

Traceback (most recent call last):
  File "/home/DriveKraft/.local/lib/python3.10/site-packages/flask/app.py", line 2525, in wsgi_app
    response = self.full_dispatch_request()
  File "/home/DriveKraft/.local/lib/python3.10/site-packages/flask/app.py", line 1822, in full_dispatch_request
    rv = self.handle_user_exception(e)
  File "/home/DriveKraft/.local/lib/python3.10/site-packages/flask/app.py", line 1820, in full_dispatch_request
    rv = self.dispatch_request()
  File "/home/DriveKraft/.local/lib/python3.10/site-packages/flask/app.py", line 1796, in dispatch_request
    return self.ensure_sync(self.view_functions[rule.endpoint])(**view_args)
  File "/home/DriveKraft/drivekraft-app-backend/./app/util.py", line 20, in wrapper
    g.session.rollback()
  File "/usr/local/lib/python3.10/site-packages/sqlalchemy/orm/session.py", line 1399, in rollback
    self._transaction.rollback(_to_root=self.future)
  File "/usr/local/lib/python3.10/site-packages/sqlalchemy/orm/session.py", line 900, in rollback
    util.raise_(rollback_err[1], with_traceback=rollback_err[2])
  File "/usr/local/lib/python3.10/site-packages/sqlalchemy/util/compat.py", line 207, in raise_
    raise exception
  File "/usr/local/lib/python3.10/site-packages/sqlalchemy/orm/session.py", line 865, in rollback
    t[1].rollback()
  File "/usr/local/lib/python3.10/site-packages/sqlalchemy/engine/base.py", line 2357, in rollback
    self._do_rollback()
  File "/usr/local/lib/python3.10/site-packages/sqlalchemy/engine/base.py", line 2561, in _do_rollback
    self._close_impl(try_deactivate=True)
  File "/usr/local/lib/python3.10/site-packages/sqlalchemy/engine/base.py", line 2544, in _close_impl
    self._connection_rollback_impl()
  File "/usr/local/lib/python3.10/site-packages/sqlalchemy/engine/base.py", line 2536, in _connection_rollback_impl
    self.connection._rollback_impl()
  File "/usr/local/lib/python3.10/site-packages/sqlalchemy/engine/base.py", line 985, in _rollback_impl
    self._handle_dbapi_exception(e, None, None, None, None)
  File "/usr/local/lib/python3.10/site-packages/sqlalchemy/engine/base.py", line 2043, in _handle_dbapi_exception
    util.raise_(
  File "/usr/local/lib/python3.10/site-packages/sqlalchemy/util/compat.py", line 207, in raise_
    raise exception
  File "/usr/local/lib/python3.10/site-packages/sqlalchemy/engine/base.py", line 983, in _rollback_impl
    self.engine.dialect.do_rollback(self.connection)
  File "/usr/local/lib/python3.10/site-packages/sqlalchemy/engine/default.py", line 682, in do_rollback
    dbapi_connection.rollback()
sqlalchemy.exc.InterfaceError: (MySQLdb._exceptions.InterfaceError) (0, '')
(Background on this error at: https://sqlalche.me/e/14/rvf5)
2024-01-12 22:30:36,950 - app - ERROR - Exception on /api/login-send-otp [POST]
Traceback (most recent call last):
  File "/usr/local/lib/python3.10/site-packages/sqlalchemy/engine/base.py", line 1819, in _execute_context
    self.dialect.do_execute(
  File "/usr/local/lib/python3.10/site-packages/sqlalchemy/engine/default.py", line 732, in do_execute
    cursor.execute(statement, parameters)
  File "/usr/local/lib/python3.10/site-packages/MySQLdb/cursors.py", line 206, in execute
    res = self._query(query)
  File "/usr/local/lib/python3.10/site-packages/MySQLdb/cursors.py", line 319, in _query
    db.query(q)
  File "/usr/local/lib/python3.10/site-packages/MySQLdb/connections.py", line 254, in query
    _mysql.connection.query(self, query)
MySQLdb._exceptions.OperationalError: (4031, 'The client was disconnected by the server because of inactivity. See wait_timeout and interactive_timeout for configuring this behavior.')

The above exception was the direct cause of the following exception:

Traceback (most recent call last):
  File "/home/DriveKraft/drivekraft-app-backend/./app/util.py", line 15, in wrapper
    result = func(*args, **kwargs)
  File "/home/DriveKraft/drivekraft-app-backend/./app/util.py", line 43, in wrapper
    return func(*args, **kwargs)
  File "/home/DriveKraft/drivekraft-app-backend/./app/Routes/otpRoutes.py", line 17, in generateNewOtp
    response = otpGenerateService.generateOtp(otpRequest).__dict__
  File "/home/DriveKraft/drivekraft-app-backend/./app/Services/otpGenerateService.py", line 22, in generateOtp
    user = userService.getUserByContact(contactNumber=request.mobile)
  File "/home/DriveKraft/drivekraft-app-backend/./app/Services/userService.py", line 84, in getUserByContact
    return userDao.getUserByContact(contactNumber)
  File "/home/DriveKraft/drivekraft-app-backend/./app/Models/DAO/userDao.py", line 35, in getUserByContact
    user = session.query(User).filter_by(contactNumber=contactNumber).one()
  File "/usr/local/lib/python3.10/site-packages/sqlalchemy/orm/query.py", line 2865, in one
    return self._iter().one()
  File "/usr/local/lib/python3.10/site-packages/sqlalchemy/orm/query.py", line 2903, in _iter
    result = self.session.execute(
  File "/usr/local/lib/python3.10/site-packages/sqlalchemy/orm/session.py", line 1696, in execute
    result = conn._execute_20(statement, params or {}, execution_options)
  File "/usr/local/lib/python3.10/site-packages/sqlalchemy/engine/base.py", line 1631, in _execute_20
    return meth(self, args_10style, kwargs_10style, execution_options)
  File "/usr/local/lib/python3.10/site-packages/sqlalchemy/sql/elements.py", line 325, in _execute_on_connection
    return connection._execute_clauseelement(
  File "/usr/local/lib/python3.10/site-packages/sqlalchemy/engine/base.py", line 1498, in _execute_clauseelement
    ret = self._execute_context(
  File "/usr/local/lib/python3.10/site-packages/sqlalchemy/engine/base.py", line 1862, in _execute_context
    self._handle_dbapi_exception(
  File "/usr/local/lib/python3.10/site-packages/sqlalchemy/engine/base.py", line 2043, in _handle_dbapi_exception
    util.raise_(
  File "/usr/local/lib/python3.10/site-packages/sqlalchemy/util/compat.py", line 207, in raise_
    raise exception
  File "/usr/local/lib/python3.10/site-packages/sqlalchemy/engine/base.py", line 1819, in _execute_context
    self.dialect.do_execute(
  File "/usr/local/lib/python3.10/site-packages/sqlalchemy/engine/default.py", line 732, in do_execute
    cursor.execute(statement, parameters)
  File "/usr/local/lib/python3.10/site-packages/MySQLdb/cursors.py", line 206, in execute
    res = self._query(query)
  File "/usr/local/lib/python3.10/site-packages/MySQLdb/cursors.py", line 319, in _query
    db.query(q)
  File "/usr/local/lib/python3.10/site-packages/MySQLdb/connections.py", line 254, in query
    _mysql.connection.query(self, query)
sqlalchemy.exc.OperationalError: (MySQLdb._exceptions.OperationalError) (4031, 'The client was disconnected by the server because of inactivity. See wait_timeout and interactive_timeout for configuring this behavior.')
[SQL: SELECT user.id AS user_id, user.name AS user_name, user.`contactNumber` AS `user_contactNumber`, user.username AS user_username, user.created AS user_created, user.updated AS user_updated, user.`firebaseId` AS `user_firebaseId`, user.`firebaseName` AS `user_firebaseName`, user.`firebaseEmail` AS `user_firebaseEmail`, user.`firebasePassword` AS `user_firebasePassword`, user.`roleId` AS `user_roleId`, user.balance AS user_balance, user.`isBlocked` AS `user_isBlocked` 
FROM user 
WHERE user.`contactNumber` = %s]
[parameters: ('918284990439',)]
(Background on this error at: https://sqlalche.me/e/14/e3q8)

During handling of the above exception, another exception occurred:

Traceback (most recent call last):
  File "/usr/local/lib/python3.10/site-packages/sqlalchemy/engine/base.py", line 983, in _rollback_impl
    self.engine.dialect.do_rollback(self.connection)
  File "/usr/local/lib/python3.10/site-packages/sqlalchemy/engine/default.py", line 682, in do_rollback
    dbapi_connection.rollback()
MySQLdb._exceptions.InterfaceError: (0, '')

The above exception was the direct cause of the following exception:

Traceback (most recent call last):
  File "/home/DriveKraft/.local/lib/python3.10/site-packages/flask/app.py", line 2525, in wsgi_app
    response = self.full_dispatch_request()
  File "/home/DriveKraft/.local/lib/python3.10/site-packages/flask/app.py", line 1822, in full_dispatch_request
    rv = self.handle_user_exception(e)
  File "/home/DriveKraft/.local/lib/python3.10/site-packages/flask/app.py", line 1820, in full_dispatch_request
    rv = self.dispatch_request()
  File "/home/DriveKraft/.local/lib/python3.10/site-packages/flask/app.py", line 1796, in dispatch_request
    return self.ensure_sync(self.view_functions[rule.endpoint])(**view_args)
  File "/home/DriveKraft/drivekraft-app-backend/./app/util.py", line 20, in wrapper
    g.session.rollback()
  File "/usr/local/lib/python3.10/site-packages/sqlalchemy/orm/session.py", line 1399, in rollback
    self._transaction.rollback(_to_root=self.future)
  File "/usr/local/lib/python3.10/site-packages/sqlalchemy/orm/session.py", line 900, in rollback
    util.raise_(rollback_err[1], with_traceback=rollback_err[2])
  File "/usr/local/lib/python3.10/site-packages/sqlalchemy/util/compat.py", line 207, in raise_
    raise exception
  File "/usr/local/lib/python3.10/site-packages/sqlalchemy/orm/session.py", line 865, in rollback
    t[1].rollback()
  File "/usr/local/lib/python3.10/site-packages/sqlalchemy/engine/base.py", line 2357, in rollback
    self._do_rollback()
  File "/usr/local/lib/python3.10/site-packages/sqlalchemy/engine/base.py", line 2561, in _do_rollback
    self._close_impl(try_deactivate=True)
  File "/usr/local/lib/python3.10/site-packages/sqlalchemy/engine/base.py", line 2544, in _close_impl
    self._connection_rollback_impl()
  File "/usr/local/lib/python3.10/site-packages/sqlalchemy/engine/base.py", line 2536, in _connection_rollback_impl
    self.connection._rollback_impl()
  File "/usr/local/lib/python3.10/site-packages/sqlalchemy/engine/base.py", line 985, in _rollback_impl
    self._handle_dbapi_exception(e, None, None, None, None)
  File "/usr/local/lib/python3.10/site-packages/sqlalchemy/engine/base.py", line 2043, in _handle_dbapi_exception
    util.raise_(
  File "/usr/local/lib/python3.10/site-packages/sqlalchemy/util/compat.py", line 207, in raise_
    raise exception
  File "/usr/local/lib/python3.10/site-packages/sqlalchemy/engine/base.py", line 983, in _rollback_impl
    self.engine.dialect.do_rollback(self.connection)
  File "/usr/local/lib/python3.10/site-packages/sqlalchemy/engine/default.py", line 682, in do_rollback
    dbapi_connection.rollback()
sqlalchemy.exc.InterfaceError: (MySQLdb._exceptions.InterfaceError) (0, '')
(Background on this error at: https://sqlalche.me/e/14/rvf5)
2024-01-12 22:35:42,123 - app - ERROR - Exception on /api/login-send-otp [POST]
Traceback (most recent call last):
  File "/usr/local/lib/python3.10/site-packages/sqlalchemy/engine/base.py", line 1819, in _execute_context
    self.dialect.do_execute(
  File "/usr/local/lib/python3.10/site-packages/sqlalchemy/engine/default.py", line 732, in do_execute
    cursor.execute(statement, parameters)
  File "/usr/local/lib/python3.10/site-packages/MySQLdb/cursors.py", line 206, in execute
    res = self._query(query)
  File "/usr/local/lib/python3.10/site-packages/MySQLdb/cursors.py", line 319, in _query
    db.query(q)
  File "/usr/local/lib/python3.10/site-packages/MySQLdb/connections.py", line 254, in query
    _mysql.connection.query(self, query)
MySQLdb._exceptions.OperationalError: (4031, 'The client was disconnected by the server because of inactivity. See wait_timeout and interactive_timeout for configuring this behavior.')

The above exception was the direct cause of the following exception:

Traceback (most recent call last):
  File "/home/DriveKraft/drivekraft-app-backend/./app/util.py", line 15, in wrapper
    result = func(*args, **kwargs)
  File "/home/DriveKraft/drivekraft-app-backend/./app/util.py", line 43, in wrapper
    return func(*args, **kwargs)
  File "/home/DriveKraft/drivekraft-app-backend/./app/Routes/otpRoutes.py", line 17, in generateNewOtp
    response = otpGenerateService.generateOtp(otpRequest).__dict__
  File "/home/DriveKraft/drivekraft-app-backend/./app/Services/otpGenerateService.py", line 22, in generateOtp
    user = userService.getUserByContact(contactNumber=request.mobile)
  File "/home/DriveKraft/drivekraft-app-backend/./app/Services/userService.py", line 84, in getUserByContact
    return userDao.getUserByContact(contactNumber)
  File "/home/DriveKraft/drivekraft-app-backend/./app/Models/DAO/userDao.py", line 35, in getUserByContact
    user = session.query(User).filter_by(contactNumber=contactNumber).one()
  File "/usr/local/lib/python3.10/site-packages/sqlalchemy/orm/query.py", line 2865, in one
    return self._iter().one()
  File "/usr/local/lib/python3.10/site-packages/sqlalchemy/orm/query.py", line 2903, in _iter
    result = self.session.execute(
  File "/usr/local/lib/python3.10/site-packages/sqlalchemy/orm/session.py", line 1696, in execute
    result = conn._execute_20(statement, params or {}, execution_options)
  File "/usr/local/lib/python3.10/site-packages/sqlalchemy/engine/base.py", line 1631, in _execute_20
    return meth(self, args_10style, kwargs_10style, execution_options)
  File "/usr/local/lib/python3.10/site-packages/sqlalchemy/sql/elements.py", line 325, in _execute_on_connection
    return connection._execute_clauseelement(
  File "/usr/local/lib/python3.10/site-packages/sqlalchemy/engine/base.py", line 1498, in _execute_clauseelement
    ret = self._execute_context(
  File "/usr/local/lib/python3.10/site-packages/sqlalchemy/engine/base.py", line 1862, in _execute_context
    self._handle_dbapi_exception(
  File "/usr/local/lib/python3.10/site-packages/sqlalchemy/engine/base.py", line 2043, in _handle_dbapi_exception
    util.raise_(
  File "/usr/local/lib/python3.10/site-packages/sqlalchemy/util/compat.py", line 207, in raise_
    raise exception
  File "/usr/local/lib/python3.10/site-packages/sqlalchemy/engine/base.py", line 1819, in _execute_context
    self.dialect.do_execute(
  File "/usr/local/lib/python3.10/site-packages/sqlalchemy/engine/default.py", line 732, in do_execute
    cursor.execute(statement, parameters)
  File "/usr/local/lib/python3.10/site-packages/MySQLdb/cursors.py", line 206, in execute
    res = self._query(query)
  File "/usr/local/lib/python3.10/site-packages/MySQLdb/cursors.py", line 319, in _query
    db.query(q)
  File "/usr/local/lib/python3.10/site-packages/MySQLdb/connections.py", line 254, in query
    _mysql.connection.query(self, query)
sqlalchemy.exc.OperationalError: (MySQLdb._exceptions.OperationalError) (4031, 'The client was disconnected by the server because of inactivity. See wait_timeout and interactive_timeout for configuring this behavior.')
[SQL: SELECT user.id AS user_id, user.name AS user_name, user.`contactNumber` AS `user_contactNumber`, user.username AS user_username, user.created AS user_created, user.updated AS user_updated, user.`firebaseId` AS `user_firebaseId`, user.`firebaseName` AS `user_firebaseName`, user.`firebaseEmail` AS `user_firebaseEmail`, user.`firebasePassword` AS `user_firebasePassword`, user.`roleId` AS `user_roleId`, user.balance AS user_balance, user.`isBlocked` AS `user_isBlocked` 
FROM user 
WHERE user.`contactNumber` = %s]
[parameters: ('918284990439',)]
(Background on this error at: https://sqlalche.me/e/14/e3q8)

During handling of the above exception, another exception occurred:

Traceback (most recent call last):
  File "/usr/local/lib/python3.10/site-packages/sqlalchemy/engine/base.py", line 983, in _rollback_impl
    self.engine.dialect.do_rollback(self.connection)
  File "/usr/local/lib/python3.10/site-packages/sqlalchemy/engine/default.py", line 682, in do_rollback
    dbapi_connection.rollback()
MySQLdb._exceptions.InterfaceError: (0, '')

The above exception was the direct cause of the following exception:

Traceback (most recent call last):
  File "/home/DriveKraft/.local/lib/python3.10/site-packages/flask/app.py", line 2525, in wsgi_app
    response = self.full_dispatch_request()
  File "/home/DriveKraft/.local/lib/python3.10/site-packages/flask/app.py", line 1822, in full_dispatch_request
    rv = self.handle_user_exception(e)
  File "/home/DriveKraft/.local/lib/python3.10/site-packages/flask/app.py", line 1820, in full_dispatch_request
    rv = self.dispatch_request()
  File "/home/DriveKraft/.local/lib/python3.10/site-packages/flask/app.py", line 1796, in dispatch_request
    return self.ensure_sync(self.view_functions[rule.endpoint])(**view_args)
  File "/home/DriveKraft/drivekraft-app-backend/./app/util.py", line 20, in wrapper
    g.session.rollback()
  File "/usr/local/lib/python3.10/site-packages/sqlalchemy/orm/session.py", line 1399, in rollback
    self._transaction.rollback(_to_root=self.future)
  File "/usr/local/lib/python3.10/site-packages/sqlalchemy/orm/session.py", line 900, in rollback
    util.raise_(rollback_err[1], with_traceback=rollback_err[2])
  File "/usr/local/lib/python3.10/site-packages/sqlalchemy/util/compat.py", line 207, in raise_
    raise exception
  File "/usr/local/lib/python3.10/site-packages/sqlalchemy/orm/session.py", line 865, in rollback
    t[1].rollback()
  File "/usr/local/lib/python3.10/site-packages/sqlalchemy/engine/base.py", line 2357, in rollback
    self._do_rollback()
  File "/usr/local/lib/python3.10/site-packages/sqlalchemy/engine/base.py", line 2561, in _do_rollback
    self._close_impl(try_deactivate=True)
  File "/usr/local/lib/python3.10/site-packages/sqlalchemy/engine/base.py", line 2544, in _close_impl
    self._connection_rollback_impl()
  File "/usr/local/lib/python3.10/site-packages/sqlalchemy/engine/base.py", line 2536, in _connection_rollback_impl
    self.connection._rollback_impl()
  File "/usr/local/lib/python3.10/site-packages/sqlalchemy/engine/base.py", line 985, in _rollback_impl
    self._handle_dbapi_exception(e, None, None, None, None)
  File "/usr/local/lib/python3.10/site-packages/sqlalchemy/engine/base.py", line 2043, in _handle_dbapi_exception
    util.raise_(
  File "/usr/local/lib/python3.10/site-packages/sqlalchemy/util/compat.py", line 207, in raise_
    raise exception
  File "/usr/local/lib/python3.10/site-packages/sqlalchemy/engine/base.py", line 983, in _rollback_impl
    self.engine.dialect.do_rollback(self.connection)
  File "/usr/local/lib/python3.10/site-packages/sqlalchemy/engine/default.py", line 682, in do_rollback
    dbapi_connection.rollback()
sqlalchemy.exc.InterfaceError: (MySQLdb._exceptions.InterfaceError) (0, '')
(Background on this error at: https://sqlalche.me/e/14/rvf5)
2024-01-12 22:57:51,444 - app - ERROR - Exception on /api/login-send-otp [POST]
Traceback (most recent call last):
  File "/usr/local/lib/python3.10/site-packages/sqlalchemy/engine/base.py", line 1819, in _execute_context
    self.dialect.do_execute(
  File "/usr/local/lib/python3.10/site-packages/sqlalchemy/engine/default.py", line 732, in do_execute
    cursor.execute(statement, parameters)
  File "/usr/local/lib/python3.10/site-packages/MySQLdb/cursors.py", line 206, in execute
    res = self._query(query)
  File "/usr/local/lib/python3.10/site-packages/MySQLdb/cursors.py", line 319, in _query
    db.query(q)
  File "/usr/local/lib/python3.10/site-packages/MySQLdb/connections.py", line 254, in query
    _mysql.connection.query(self, query)
MySQLdb._exceptions.OperationalError: (4031, 'The client was disconnected by the server because of inactivity. See wait_timeout and interactive_timeout for configuring this behavior.')

The above exception was the direct cause of the following exception:

Traceback (most recent call last):
  File "/home/DriveKraft/drivekraft-app-backend/./app/util.py", line 15, in wrapper
    result = func(*args, **kwargs)
  File "/home/DriveKraft/drivekraft-app-backend/./app/util.py", line 43, in wrapper
    return func(*args, **kwargs)
  File "/home/DriveKraft/drivekraft-app-backend/./app/Routes/otpRoutes.py", line 19, in generateNewOtp
    response = otpGenerateService.generateOtp(otpRequest).__dict__
  File "/home/DriveKraft/drivekraft-app-backend/./app/Services/otpGenerateService.py", line 22, in generateOtp
    user = userService.getUserByContact(contactNumber=request.mobile)
  File "/home/DriveKraft/drivekraft-app-backend/./app/Services/userService.py", line 84, in getUserByContact
    return userDao.getUserByContact(contactNumber)
  File "/home/DriveKraft/drivekraft-app-backend/./app/Models/DAO/userDao.py", line 35, in getUserByContact
    user = session.query(User).filter_by(contactNumber=contactNumber).one()
  File "/usr/local/lib/python3.10/site-packages/sqlalchemy/orm/query.py", line 2865, in one
    return self._iter().one()
  File "/usr/local/lib/python3.10/site-packages/sqlalchemy/orm/query.py", line 2903, in _iter
    result = self.session.execute(
  File "/usr/local/lib/python3.10/site-packages/sqlalchemy/orm/session.py", line 1696, in execute
    result = conn._execute_20(statement, params or {}, execution_options)
  File "/usr/local/lib/python3.10/site-packages/sqlalchemy/engine/base.py", line 1631, in _execute_20
    return meth(self, args_10style, kwargs_10style, execution_options)
  File "/usr/local/lib/python3.10/site-packages/sqlalchemy/sql/elements.py", line 325, in _execute_on_connection
    return connection._execute_clauseelement(
  File "/usr/local/lib/python3.10/site-packages/sqlalchemy/engine/base.py", line 1498, in _execute_clauseelement
    ret = self._execute_context(
  File "/usr/local/lib/python3.10/site-packages/sqlalchemy/engine/base.py", line 1862, in _execute_context
    self._handle_dbapi_exception(
  File "/usr/local/lib/python3.10/site-packages/sqlalchemy/engine/base.py", line 2043, in _handle_dbapi_exception
    util.raise_(
  File "/usr/local/lib/python3.10/site-packages/sqlalchemy/util/compat.py", line 207, in raise_
    raise exception
  File "/usr/local/lib/python3.10/site-packages/sqlalchemy/engine/base.py", line 1819, in _execute_context
    self.dialect.do_execute(
  File "/usr/local/lib/python3.10/site-packages/sqlalchemy/engine/default.py", line 732, in do_execute
    cursor.execute(statement, parameters)
  File "/usr/local/lib/python3.10/site-packages/MySQLdb/cursors.py", line 206, in execute
    res = self._query(query)
  File "/usr/local/lib/python3.10/site-packages/MySQLdb/cursors.py", line 319, in _query
    db.query(q)
  File "/usr/local/lib/python3.10/site-packages/MySQLdb/connections.py", line 254, in query
    _mysql.connection.query(self, query)
sqlalchemy.exc.OperationalError: (MySQLdb._exceptions.OperationalError) (4031, 'The client was disconnected by the server because of inactivity. See wait_timeout and interactive_timeout for configuring this behavior.')
[SQL: SELECT user.id AS user_id, user.name AS user_name, user.`contactNumber` AS `user_contactNumber`, user.username AS user_username, user.created AS user_created, user.updated AS user_updated, user.`firebaseId` AS `user_firebaseId`, user.`firebaseName` AS `user_firebaseName`, user.`firebaseEmail` AS `user_firebaseEmail`, user.`firebasePassword` AS `user_firebasePassword`, user.`roleId` AS `user_roleId`, user.balance AS user_balance, user.`isBlocked` AS `user_isBlocked` 
FROM user 
WHERE user.`contactNumber` = %s]
[parameters: ('918284990439',)]
(Background on this error at: https://sqlalche.me/e/14/e3q8)

During handling of the above exception, another exception occurred:

Traceback (most recent call last):
  File "/usr/local/lib/python3.10/site-packages/sqlalchemy/engine/base.py", line 983, in _rollback_impl
    self.engine.dialect.do_rollback(self.connection)
  File "/usr/local/lib/python3.10/site-packages/sqlalchemy/engine/default.py", line 682, in do_rollback
    dbapi_connection.rollback()
MySQLdb._exceptions.InterfaceError: (0, '')

The above exception was the direct cause of the following exception:

Traceback (most recent call last):
  File "/home/DriveKraft/.local/lib/python3.10/site-packages/flask/app.py", line 2525, in wsgi_app
    response = self.full_dispatch_request()
  File "/home/DriveKraft/.local/lib/python3.10/site-packages/flask/app.py", line 1822, in full_dispatch_request
    rv = self.handle_user_exception(e)
  File "/home/DriveKraft/.local/lib/python3.10/site-packages/flask/app.py", line 1820, in full_dispatch_request
    rv = self.dispatch_request()
  File "/home/DriveKraft/.local/lib/python3.10/site-packages/flask/app.py", line 1796, in dispatch_request
    return self.ensure_sync(self.view_functions[rule.endpoint])(**view_args)
  File "/home/DriveKraft/drivekraft-app-backend/./app/util.py", line 20, in wrapper
    g.session.rollback()
  File "/usr/local/lib/python3.10/site-packages/sqlalchemy/orm/session.py", line 1399, in rollback
    self._transaction.rollback(_to_root=self.future)
  File "/usr/local/lib/python3.10/site-packages/sqlalchemy/orm/session.py", line 900, in rollback
    util.raise_(rollback_err[1], with_traceback=rollback_err[2])
  File "/usr/local/lib/python3.10/site-packages/sqlalchemy/util/compat.py", line 207, in raise_
    raise exception
  File "/usr/local/lib/python3.10/site-packages/sqlalchemy/orm/session.py", line 865, in rollback
    t[1].rollback()
  File "/usr/local/lib/python3.10/site-packages/sqlalchemy/engine/base.py", line 2357, in rollback
    self._do_rollback()
  File "/usr/local/lib/python3.10/site-packages/sqlalchemy/engine/base.py", line 2561, in _do_rollback
    self._close_impl(try_deactivate=True)
  File "/usr/local/lib/python3.10/site-packages/sqlalchemy/engine/base.py", line 2544, in _close_impl
    self._connection_rollback_impl()
  File "/usr/local/lib/python3.10/site-packages/sqlalchemy/engine/base.py", line 2536, in _connection_rollback_impl
    self.connection._rollback_impl()
  File "/usr/local/lib/python3.10/site-packages/sqlalchemy/engine/base.py", line 985, in _rollback_impl
    self._handle_dbapi_exception(e, None, None, None, None)
  File "/usr/local/lib/python3.10/site-packages/sqlalchemy/engine/base.py", line 2043, in _handle_dbapi_exception
    util.raise_(
  File "/usr/local/lib/python3.10/site-packages/sqlalchemy/util/compat.py", line 207, in raise_
    raise exception
  File "/usr/local/lib/python3.10/site-packages/sqlalchemy/engine/base.py", line 983, in _rollback_impl
    self.engine.dialect.do_rollback(self.connection)
  File "/usr/local/lib/python3.10/site-packages/sqlalchemy/engine/default.py", line 682, in do_rollback
    dbapi_connection.rollback()
sqlalchemy.exc.InterfaceError: (MySQLdb._exceptions.InterfaceError) (0, '')
(Background on this error at: https://sqlalche.me/e/14/rvf5)
2024-01-12 23:24:37,717 - app - ERROR - Exception on /api/login-send-otp [POST]
Traceback (most recent call last):
  File "/usr/local/lib/python3.10/site-packages/sqlalchemy/engine/base.py", line 1819, in _execute_context
    self.dialect.do_execute(
  File "/usr/local/lib/python3.10/site-packages/sqlalchemy/engine/default.py", line 732, in do_execute
    cursor.execute(statement, parameters)
  File "/usr/local/lib/python3.10/site-packages/MySQLdb/cursors.py", line 206, in execute
    res = self._query(query)
  File "/usr/local/lib/python3.10/site-packages/MySQLdb/cursors.py", line 319, in _query
    db.query(q)
  File "/usr/local/lib/python3.10/site-packages/MySQLdb/connections.py", line 254, in query
    _mysql.connection.query(self, query)
MySQLdb._exceptions.OperationalError: (4031, 'The client was disconnected by the server because of inactivity. See wait_timeout and interactive_timeout for configuring this behavior.')

The above exception was the direct cause of the following exception:

Traceback (most recent call last):
  File "/home/DriveKraft/drivekraft-app-backend/./app/util.py", line 15, in wrapper
    result = func(*args, **kwargs)
  File "/home/DriveKraft/drivekraft-app-backend/./app/util.py", line 43, in wrapper
    return func(*args, **kwargs)
  File "/home/DriveKraft/drivekraft-app-backend/./app/Routes/otpRoutes.py", line 19, in generateNewOtp
    response = otpGenerateService.generateOtp(otpRequest).__dict__
  File "/home/DriveKraft/drivekraft-app-backend/./app/Services/otpGenerateService.py", line 22, in generateOtp
    user = userService.getUserByContact(contactNumber=request.mobile)
  File "/home/DriveKraft/drivekraft-app-backend/./app/Services/userService.py", line 84, in getUserByContact
    return userDao.getUserByContact(contactNumber)
  File "/home/DriveKraft/drivekraft-app-backend/./app/Models/DAO/userDao.py", line 35, in getUserByContact
    user = session.query(User).filter_by(contactNumber=contactNumber).one()
  File "/usr/local/lib/python3.10/site-packages/sqlalchemy/orm/query.py", line 2865, in one
    return self._iter().one()
  File "/usr/local/lib/python3.10/site-packages/sqlalchemy/orm/query.py", line 2903, in _iter
    result = self.session.execute(
  File "/usr/local/lib/python3.10/site-packages/sqlalchemy/orm/session.py", line 1696, in execute
    result = conn._execute_20(statement, params or {}, execution_options)
  File "/usr/local/lib/python3.10/site-packages/sqlalchemy/engine/base.py", line 1631, in _execute_20
    return meth(self, args_10style, kwargs_10style, execution_options)
  File "/usr/local/lib/python3.10/site-packages/sqlalchemy/sql/elements.py", line 325, in _execute_on_connection
    return connection._execute_clauseelement(
  File "/usr/local/lib/python3.10/site-packages/sqlalchemy/engine/base.py", line 1498, in _execute_clauseelement
    ret = self._execute_context(
  File "/usr/local/lib/python3.10/site-packages/sqlalchemy/engine/base.py", line 1862, in _execute_context
    self._handle_dbapi_exception(
  File "/usr/local/lib/python3.10/site-packages/sqlalchemy/engine/base.py", line 2043, in _handle_dbapi_exception
    util.raise_(
  File "/usr/local/lib/python3.10/site-packages/sqlalchemy/util/compat.py", line 207, in raise_
    raise exception
  File "/usr/local/lib/python3.10/site-packages/sqlalchemy/engine/base.py", line 1819, in _execute_context
    self.dialect.do_execute(
  File "/usr/local/lib/python3.10/site-packages/sqlalchemy/engine/default.py", line 732, in do_execute
    cursor.execute(statement, parameters)
  File "/usr/local/lib/python3.10/site-packages/MySQLdb/cursors.py", line 206, in execute
    res = self._query(query)
  File "/usr/local/lib/python3.10/site-packages/MySQLdb/cursors.py", line 319, in _query
    db.query(q)
  File "/usr/local/lib/python3.10/site-packages/MySQLdb/connections.py", line 254, in query
    _mysql.connection.query(self, query)
sqlalchemy.exc.OperationalError: (MySQLdb._exceptions.OperationalError) (4031, 'The client was disconnected by the server because of inactivity. See wait_timeout and interactive_timeout for configuring this behavior.')
[SQL: SELECT user.id AS user_id, user.name AS user_name, user.`contactNumber` AS `user_contactNumber`, user.username AS user_username, user.created AS user_created, user.updated AS user_updated, user.`firebaseId` AS `user_firebaseId`, user.`firebaseName` AS `user_firebaseName`, user.`firebaseEmail` AS `user_firebaseEmail`, user.`firebasePassword` AS `user_firebasePassword`, user.`roleId` AS `user_roleId`, user.balance AS user_balance, user.`isBlocked` AS `user_isBlocked` 
FROM user 
WHERE user.`contactNumber` = %s]
[parameters: ('918284990439',)]
(Background on this error at: https://sqlalche.me/e/14/e3q8)

During handling of the above exception, another exception occurred:

Traceback (most recent call last):
  File "/usr/local/lib/python3.10/site-packages/sqlalchemy/engine/base.py", line 983, in _rollback_impl
    self.engine.dialect.do_rollback(self.connection)
  File "/usr/local/lib/python3.10/site-packages/sqlalchemy/engine/default.py", line 682, in do_rollback
    dbapi_connection.rollback()
MySQLdb._exceptions.InterfaceError: (0, '')

The above exception was the direct cause of the following exception:

Traceback (most recent call last):
  File "/home/DriveKraft/.local/lib/python3.10/site-packages/flask/app.py", line 2525, in wsgi_app
    response = self.full_dispatch_request()
  File "/home/DriveKraft/.local/lib/python3.10/site-packages/flask/app.py", line 1822, in full_dispatch_request
    rv = self.handle_user_exception(e)
  File "/home/DriveKraft/.local/lib/python3.10/site-packages/flask/app.py", line 1820, in full_dispatch_request
    rv = self.dispatch_request()
  File "/home/DriveKraft/.local/lib/python3.10/site-packages/flask/app.py", line 1796, in dispatch_request
    return self.ensure_sync(self.view_functions[rule.endpoint])(**view_args)
  File "/home/DriveKraft/drivekraft-app-backend/./app/util.py", line 20, in wrapper
    g.session.rollback()
  File "/usr/local/lib/python3.10/site-packages/sqlalchemy/orm/session.py", line 1399, in rollback
    self._transaction.rollback(_to_root=self.future)
  File "/usr/local/lib/python3.10/site-packages/sqlalchemy/orm/session.py", line 900, in rollback
    util.raise_(rollback_err[1], with_traceback=rollback_err[2])
  File "/usr/local/lib/python3.10/site-packages/sqlalchemy/util/compat.py", line 207, in raise_
    raise exception
  File "/usr/local/lib/python3.10/site-packages/sqlalchemy/orm/session.py", line 865, in rollback
    t[1].rollback()
  File "/usr/local/lib/python3.10/site-packages/sqlalchemy/engine/base.py", line 2357, in rollback
    self._do_rollback()
  File "/usr/local/lib/python3.10/site-packages/sqlalchemy/engine/base.py", line 2561, in _do_rollback
    self._close_impl(try_deactivate=True)
  File "/usr/local/lib/python3.10/site-packages/sqlalchemy/engine/base.py", line 2544, in _close_impl
    self._connection_rollback_impl()
  File "/usr/local/lib/python3.10/site-packages/sqlalchemy/engine/base.py", line 2536, in _connection_rollback_impl
    self.connection._rollback_impl()
  File "/usr/local/lib/python3.10/site-packages/sqlalchemy/engine/base.py", line 985, in _rollback_impl
    self._handle_dbapi_exception(e, None, None, None, None)
  File "/usr/local/lib/python3.10/site-packages/sqlalchemy/engine/base.py", line 2043, in _handle_dbapi_exception
    util.raise_(
  File "/usr/local/lib/python3.10/site-packages/sqlalchemy/util/compat.py", line 207, in raise_
    raise exception
  File "/usr/local/lib/python3.10/site-packages/sqlalchemy/engine/base.py", line 983, in _rollback_impl
    self.engine.dialect.do_rollback(self.connection)
  File "/usr/local/lib/python3.10/site-packages/sqlalchemy/engine/default.py", line 682, in do_rollback
    dbapi_connection.rollback()
sqlalchemy.exc.InterfaceError: (MySQLdb._exceptions.InterfaceError) (0, '')
(Background on this error at: https://sqlalche.me/e/14/rvf5)
2024-01-12 23:24:54,260 - app - ERROR - Exception on /api/login [POST]
Traceback (most recent call last):
  File "/home/DriveKraft/.local/lib/python3.10/site-packages/flask/app.py", line 2525, in wsgi_app
    response = self.full_dispatch_request()
  File "/home/DriveKraft/.local/lib/python3.10/site-packages/flask/app.py", line 1822, in full_dispatch_request
    rv = self.handle_user_exception(e)
  File "/home/DriveKraft/.local/lib/python3.10/site-packages/flask/app.py", line 1820, in full_dispatch_request
    rv = self.dispatch_request()
  File "/home/DriveKraft/.local/lib/python3.10/site-packages/flask/app.py", line 1796, in dispatch_request
    return self.ensure_sync(self.view_functions[rule.endpoint])(**view_args)
  File "/home/DriveKraft/drivekraft-app-backend/./app/util.py", line 21, in wrapper
    raise e
  File "/home/DriveKraft/drivekraft-app-backend/./app/util.py", line 15, in wrapper
    result = func(*args, **kwargs)
  File "/home/DriveKraft/drivekraft-app-backend/./app/util.py", line 43, in wrapper
    return func(*args, **kwargs)
  File "/home/DriveKraft/drivekraft-app-backend/./app/Routes/otpRoutes.py", line 29, in verifyOtp
    response = otpVerificationService.verifyOtp(otpVerifyRequest).__dict__
  File "/home/DriveKraft/drivekraft-app-backend/./app/Services/otpVerificationService.py", line 15, in verifyOtp
    logging.info("userOTP is "+str(request.otp)+" and required otp is"+ str(otp) )
NameError: name 'logging' is not defined
2024-01-12 23:24:57,783 - app - ERROR - Exception on /api/login [POST]
Traceback (most recent call last):
  File "/home/DriveKraft/.local/lib/python3.10/site-packages/flask/app.py", line 2525, in wsgi_app
    response = self.full_dispatch_request()
  File "/home/DriveKraft/.local/lib/python3.10/site-packages/flask/app.py", line 1822, in full_dispatch_request
    rv = self.handle_user_exception(e)
  File "/home/DriveKraft/.local/lib/python3.10/site-packages/flask/app.py", line 1820, in full_dispatch_request
    rv = self.dispatch_request()
  File "/home/DriveKraft/.local/lib/python3.10/site-packages/flask/app.py", line 1796, in dispatch_request
    return self.ensure_sync(self.view_functions[rule.endpoint])(**view_args)
  File "/home/DriveKraft/drivekraft-app-backend/./app/util.py", line 21, in wrapper
    raise e
  File "/home/DriveKraft/drivekraft-app-backend/./app/util.py", line 15, in wrapper
    result = func(*args, **kwargs)
  File "/home/DriveKraft/drivekraft-app-backend/./app/util.py", line 43, in wrapper
    return func(*args, **kwargs)
  File "/home/DriveKraft/drivekraft-app-backend/./app/Routes/otpRoutes.py", line 29, in verifyOtp
    response = otpVerificationService.verifyOtp(otpVerifyRequest).__dict__
  File "/home/DriveKraft/drivekraft-app-backend/./app/Services/otpVerificationService.py", line 15, in verifyOtp
    logging.info("userOTP is "+str(request.otp)+" and required otp is"+ str(otp) )
NameError: name 'logging' is not defined
2024-01-12 23:25:52,819 - app - ERROR - Exception on /api/login [POST]
Traceback (most recent call last):
  File "/home/DriveKraft/.local/lib/python3.10/site-packages/flask/app.py", line 2525, in wsgi_app
    response = self.full_dispatch_request()
  File "/home/DriveKraft/.local/lib/python3.10/site-packages/flask/app.py", line 1822, in full_dispatch_request
    rv = self.handle_user_exception(e)
  File "/home/DriveKraft/.local/lib/python3.10/site-packages/flask/app.py", line 1820, in full_dispatch_request
    rv = self.dispatch_request()
  File "/home/DriveKraft/.local/lib/python3.10/site-packages/flask/app.py", line 1796, in dispatch_request
    return self.ensure_sync(self.view_functions[rule.endpoint])(**view_args)
  File "/home/DriveKraft/drivekraft-app-backend/./app/util.py", line 21, in wrapper
    raise e
  File "/home/DriveKraft/drivekraft-app-backend/./app/util.py", line 15, in wrapper
    result = func(*args, **kwargs)
  File "/home/DriveKraft/drivekraft-app-backend/./app/util.py", line 43, in wrapper
    return func(*args, **kwargs)
  File "/home/DriveKraft/drivekraft-app-backend/./app/Routes/otpRoutes.py", line 29, in verifyOtp
    response = otpVerificationService.verifyOtp(otpVerifyRequest).__dict__
  File "/home/DriveKraft/drivekraft-app-backend/./app/Services/otpVerificationService.py", line 15, in verifyOtp
    logging.info("userOTP is "+str(request.otp)+" and required otp is"+ str(otp) )
NameError: name 'logging' is not defined
2024-01-12 23:41:08,439 - app - ERROR - Exception on /api/role [GET]
Traceback (most recent call last):
  File "/home/DriveKraft/.local/lib/python3.10/site-packages/flask/app.py", line 2525, in wsgi_app
    response = self.full_dispatch_request()
  File "/home/DriveKraft/.local/lib/python3.10/site-packages/flask/app.py", line 1822, in full_dispatch_request
    rv = self.handle_user_exception(e)
  File "/home/DriveKraft/.local/lib/python3.10/site-packages/flask/app.py", line 1820, in full_dispatch_request
    rv = self.dispatch_request()
  File "/home/DriveKraft/.local/lib/python3.10/site-packages/flask/app.py", line 1796, in dispatch_request
    return self.ensure_sync(self.view_functions[rule.endpoint])(**view_args)
  File "/home/DriveKraft/drivekraft-app-backend/./app/util.py", line 21, in wrapper
    raise e
  File "/home/DriveKraft/drivekraft-app-backend/./app/util.py", line 15, in wrapper
    result = func(*args, **kwargs)
  File "/home/DriveKraft/drivekraft-app-backend/./app/authenticate.py", line 16, in wrapper
    return func(*args, **kwargs)
  File "/home/DriveKraft/drivekraft-app-backend/./app/util.py", line 43, in wrapper
    return func(*args, **kwargs)
  File "/home/DriveKraft/drivekraft-app-backend/./app/Routes/roleRoutes.py", line 15, in getRole
    response = roleService.getUserRole().__dict__
  File "/home/DriveKraft/drivekraft-app-backend/./app/Services/roleService.py", line 17, in getUserRole
    logging.info(jsonify(response))
  File "/home/DriveKraft/.local/lib/python3.10/site-packages/flask/json/__init__.py", line 342, in jsonify
    return current_app.json.response(*args, **kwargs)
  File "/home/DriveKraft/.local/lib/python3.10/site-packages/flask/json/provider.py", line 309, in response
    f"{self.dumps(obj, **dump_args)}\n", mimetype=mimetype
  File "/home/DriveKraft/.local/lib/python3.10/site-packages/flask/json/provider.py", line 230, in dumps
    return json.dumps(obj, **kwargs)
  File "/usr/local/lib/python3.10/json/__init__.py", line 238, in dumps
    **kw).encode(obj)
  File "/usr/local/lib/python3.10/json/encoder.py", line 199, in encode
    chunks = self.iterencode(o, _one_shot=True)
  File "/usr/local/lib/python3.10/json/encoder.py", line 257, in iterencode
    return _iterencode(o, 0)
  File "/home/DriveKraft/.local/lib/python3.10/site-packages/flask/json/provider.py", line 122, in _default
    raise TypeError(f"Object of type {type(o).__name__} is not JSON serializable")
TypeError: Object of type Role is not JSON serializable
2024-01-12 23:49:05,958 - app - ERROR - Exception on /api/role [GET]
Traceback (most recent call last):
  File "/usr/local/lib/python3.10/site-packages/sqlalchemy/engine/base.py", line 1819, in _execute_context
    self.dialect.do_execute(
  File "/usr/local/lib/python3.10/site-packages/sqlalchemy/engine/default.py", line 732, in do_execute
    cursor.execute(statement, parameters)
  File "/usr/local/lib/python3.10/site-packages/MySQLdb/cursors.py", line 206, in execute
    res = self._query(query)
  File "/usr/local/lib/python3.10/site-packages/MySQLdb/cursors.py", line 319, in _query
    db.query(q)
  File "/usr/local/lib/python3.10/site-packages/MySQLdb/connections.py", line 254, in query
    _mysql.connection.query(self, query)
MySQLdb._exceptions.OperationalError: (4031, 'The client was disconnected by the server because of inactivity. See wait_timeout and interactive_timeout for configuring this behavior.')

The above exception was the direct cause of the following exception:

Traceback (most recent call last):
  File "/home/DriveKraft/drivekraft-app-backend/./app/util.py", line 15, in wrapper
    result = func(*args, **kwargs)
  File "/home/DriveKraft/drivekraft-app-backend/./app/authenticate.py", line 14, in wrapper
    if verify_token(tokenValue):
  File "/home/DriveKraft/drivekraft-app-backend/./app/authenticate.py", line 25, in verify_token
    token = getToken(tokenValue=tokenValue)
  File "/home/DriveKraft/.local/lib/python3.10/site-packages/flask_caching/__init__.py", line 872, in decorated_function
    rv = self._call_fn(f, *args, **kwargs)
  File "/home/DriveKraft/.local/lib/python3.10/site-packages/flask_caching/__init__.py", line 175, in _call_fn
    return ensure_sync(fn)(*args, **kwargs)
  File "/home/DriveKraft/drivekraft-app-backend/./app/Models/DAO/tokenDAO.py", line 28, in getToken
    and_(Token.value == tokenValue, Token.created >= now - timedelta(hours=24))).one()
  File "/usr/local/lib/python3.10/site-packages/sqlalchemy/orm/query.py", line 2865, in one
    return self._iter().one()
  File "/usr/local/lib/python3.10/site-packages/sqlalchemy/orm/query.py", line 2903, in _iter
    result = self.session.execute(
  File "/usr/local/lib/python3.10/site-packages/sqlalchemy/orm/session.py", line 1696, in execute
    result = conn._execute_20(statement, params or {}, execution_options)
  File "/usr/local/lib/python3.10/site-packages/sqlalchemy/engine/base.py", line 1631, in _execute_20
    return meth(self, args_10style, kwargs_10style, execution_options)
  File "/usr/local/lib/python3.10/site-packages/sqlalchemy/sql/elements.py", line 325, in _execute_on_connection
    return connection._execute_clauseelement(
  File "/usr/local/lib/python3.10/site-packages/sqlalchemy/engine/base.py", line 1498, in _execute_clauseelement
    ret = self._execute_context(
  File "/usr/local/lib/python3.10/site-packages/sqlalchemy/engine/base.py", line 1862, in _execute_context
    self._handle_dbapi_exception(
  File "/usr/local/lib/python3.10/site-packages/sqlalchemy/engine/base.py", line 2043, in _handle_dbapi_exception
    util.raise_(
  File "/usr/local/lib/python3.10/site-packages/sqlalchemy/util/compat.py", line 207, in raise_
    raise exception
  File "/usr/local/lib/python3.10/site-packages/sqlalchemy/engine/base.py", line 1819, in _execute_context
    self.dialect.do_execute(
  File "/usr/local/lib/python3.10/site-packages/sqlalchemy/engine/default.py", line 732, in do_execute
    cursor.execute(statement, parameters)
  File "/usr/local/lib/python3.10/site-packages/MySQLdb/cursors.py", line 206, in execute
    res = self._query(query)
  File "/usr/local/lib/python3.10/site-packages/MySQLdb/cursors.py", line 319, in _query
    db.query(q)
  File "/usr/local/lib/python3.10/site-packages/MySQLdb/connections.py", line 254, in query
    _mysql.connection.query(self, query)
sqlalchemy.exc.OperationalError: (MySQLdb._exceptions.OperationalError) (4031, 'The client was disconnected by the server because of inactivity. See wait_timeout and interactive_timeout for configuring this behavior.')
[SQL: SELECT token.id AS token_id, token.`userId` AS `token_userId`, token.value AS token_value, token.created AS token_created, token.expired AS token_expired 
FROM token 
WHERE token.value = %s AND token.created >= %s]
[parameters: ('FPXI55U15SS20KGMF20LQCG34NN8VA5ZZKHJ7892LMIK2DLY87', datetime.datetime(2024, 1, 12, 5, 19, 5, 955836))]
(Background on this error at: https://sqlalche.me/e/14/e3q8)

During handling of the above exception, another exception occurred:

Traceback (most recent call last):
  File "/usr/local/lib/python3.10/site-packages/sqlalchemy/engine/base.py", line 983, in _rollback_impl
    self.engine.dialect.do_rollback(self.connection)
  File "/usr/local/lib/python3.10/site-packages/sqlalchemy/engine/default.py", line 682, in do_rollback
    dbapi_connection.rollback()
MySQLdb._exceptions.InterfaceError: (0, '')

The above exception was the direct cause of the following exception:

Traceback (most recent call last):
  File "/home/DriveKraft/.local/lib/python3.10/site-packages/flask/app.py", line 2525, in wsgi_app
    response = self.full_dispatch_request()
  File "/home/DriveKraft/.local/lib/python3.10/site-packages/flask/app.py", line 1822, in full_dispatch_request
    rv = self.handle_user_exception(e)
  File "/home/DriveKraft/.local/lib/python3.10/site-packages/flask/app.py", line 1820, in full_dispatch_request
    rv = self.dispatch_request()
  File "/home/DriveKraft/.local/lib/python3.10/site-packages/flask/app.py", line 1796, in dispatch_request
    return self.ensure_sync(self.view_functions[rule.endpoint])(**view_args)
  File "/home/DriveKraft/drivekraft-app-backend/./app/util.py", line 20, in wrapper
    g.session.rollback()
  File "/usr/local/lib/python3.10/site-packages/sqlalchemy/orm/session.py", line 1399, in rollback
    self._transaction.rollback(_to_root=self.future)
  File "/usr/local/lib/python3.10/site-packages/sqlalchemy/orm/session.py", line 900, in rollback
    util.raise_(rollback_err[1], with_traceback=rollback_err[2])
  File "/usr/local/lib/python3.10/site-packages/sqlalchemy/util/compat.py", line 207, in raise_
    raise exception
  File "/usr/local/lib/python3.10/site-packages/sqlalchemy/orm/session.py", line 865, in rollback
    t[1].rollback()
  File "/usr/local/lib/python3.10/site-packages/sqlalchemy/engine/base.py", line 2357, in rollback
    self._do_rollback()
  File "/usr/local/lib/python3.10/site-packages/sqlalchemy/engine/base.py", line 2561, in _do_rollback
    self._close_impl(try_deactivate=True)
  File "/usr/local/lib/python3.10/site-packages/sqlalchemy/engine/base.py", line 2544, in _close_impl
    self._connection_rollback_impl()
  File "/usr/local/lib/python3.10/site-packages/sqlalchemy/engine/base.py", line 2536, in _connection_rollback_impl
    self.connection._rollback_impl()
  File "/usr/local/lib/python3.10/site-packages/sqlalchemy/engine/base.py", line 985, in _rollback_impl
    self._handle_dbapi_exception(e, None, None, None, None)
  File "/usr/local/lib/python3.10/site-packages/sqlalchemy/engine/base.py", line 2043, in _handle_dbapi_exception
    util.raise_(
  File "/usr/local/lib/python3.10/site-packages/sqlalchemy/util/compat.py", line 207, in raise_
    raise exception
  File "/usr/local/lib/python3.10/site-packages/sqlalchemy/engine/base.py", line 983, in _rollback_impl
    self.engine.dialect.do_rollback(self.connection)
  File "/usr/local/lib/python3.10/site-packages/sqlalchemy/engine/default.py", line 682, in do_rollback
    dbapi_connection.rollback()
sqlalchemy.exc.InterfaceError: (MySQLdb._exceptions.InterfaceError) (0, '')
(Background on this error at: https://sqlalche.me/e/14/rvf5)
2024-01-12 23:49:43,349 - app - ERROR - Exception on /api/role [GET]
Traceback (most recent call last):
  File "/home/DriveKraft/.local/lib/python3.10/site-packages/flask/app.py", line 2525, in wsgi_app
    response = self.full_dispatch_request()
  File "/home/DriveKraft/.local/lib/python3.10/site-packages/flask/app.py", line 1822, in full_dispatch_request
    rv = self.handle_user_exception(e)
  File "/home/DriveKraft/.local/lib/python3.10/site-packages/flask/app.py", line 1820, in full_dispatch_request
    rv = self.dispatch_request()
  File "/home/DriveKraft/.local/lib/python3.10/site-packages/flask/app.py", line 1796, in dispatch_request
    return self.ensure_sync(self.view_functions[rule.endpoint])(**view_args)
  File "/home/DriveKraft/drivekraft-app-backend/./app/util.py", line 21, in wrapper
    raise e
  File "/home/DriveKraft/drivekraft-app-backend/./app/util.py", line 15, in wrapper
    result = func(*args, **kwargs)
  File "/home/DriveKraft/drivekraft-app-backend/./app/authenticate.py", line 16, in wrapper
    return func(*args, **kwargs)
  File "/home/DriveKraft/drivekraft-app-backend/./app/util.py", line 43, in wrapper
    return func(*args, **kwargs)
  File "/home/DriveKraft/drivekraft-app-backend/./app/Routes/roleRoutes.py", line 15, in getRole
    response = roleService.getUserRole().__dict__
  File "/home/DriveKraft/drivekraft-app-backend/./app/Services/roleService.py", line 17, in getUserRole
    logging.info(jsonify(response))
  File "/home/DriveKraft/.local/lib/python3.10/site-packages/flask/json/__init__.py", line 342, in jsonify
    return current_app.json.response(*args, **kwargs)
  File "/home/DriveKraft/.local/lib/python3.10/site-packages/flask/json/provider.py", line 309, in response
    f"{self.dumps(obj, **dump_args)}\n", mimetype=mimetype
  File "/home/DriveKraft/.local/lib/python3.10/site-packages/flask/json/provider.py", line 230, in dumps
    return json.dumps(obj, **kwargs)
  File "/usr/local/lib/python3.10/json/__init__.py", line 238, in dumps
    **kw).encode(obj)
  File "/usr/local/lib/python3.10/json/encoder.py", line 199, in encode
    chunks = self.iterencode(o, _one_shot=True)
  File "/usr/local/lib/python3.10/json/encoder.py", line 257, in iterencode
    return _iterencode(o, 0)
  File "/home/DriveKraft/.local/lib/python3.10/site-packages/flask/json/provider.py", line 122, in _default
    raise TypeError(f"Object of type {type(o).__name__} is not JSON serializable")
TypeError: Object of type Role is not JSON serializable
2024-01-12 23:49:53,029 - app - ERROR - Exception on /api/role [GET]
Traceback (most recent call last):
  File "/home/DriveKraft/.local/lib/python3.10/site-packages/flask/app.py", line 2525, in wsgi_app
    response = self.full_dispatch_request()
  File "/home/DriveKraft/.local/lib/python3.10/site-packages/flask/app.py", line 1822, in full_dispatch_request
    rv = self.handle_user_exception(e)
  File "/home/DriveKraft/.local/lib/python3.10/site-packages/flask/app.py", line 1820, in full_dispatch_request
    rv = self.dispatch_request()
  File "/home/DriveKraft/.local/lib/python3.10/site-packages/flask/app.py", line 1796, in dispatch_request
    return self.ensure_sync(self.view_functions[rule.endpoint])(**view_args)
  File "/home/DriveKraft/drivekraft-app-backend/./app/util.py", line 21, in wrapper
    raise e
  File "/home/DriveKraft/drivekraft-app-backend/./app/util.py", line 15, in wrapper
    result = func(*args, **kwargs)
  File "/home/DriveKraft/drivekraft-app-backend/./app/authenticate.py", line 16, in wrapper
    return func(*args, **kwargs)
  File "/home/DriveKraft/drivekraft-app-backend/./app/util.py", line 43, in wrapper
    return func(*args, **kwargs)
  File "/home/DriveKraft/drivekraft-app-backend/./app/Routes/roleRoutes.py", line 15, in getRole
    response = roleService.getUserRole().__dict__
  File "/home/DriveKraft/drivekraft-app-backend/./app/Services/roleService.py", line 17, in getUserRole
    logging.info(jsonify(response))
  File "/home/DriveKraft/.local/lib/python3.10/site-packages/flask/json/__init__.py", line 342, in jsonify
    return current_app.json.response(*args, **kwargs)
  File "/home/DriveKraft/.local/lib/python3.10/site-packages/flask/json/provider.py", line 309, in response
    f"{self.dumps(obj, **dump_args)}\n", mimetype=mimetype
  File "/home/DriveKraft/.local/lib/python3.10/site-packages/flask/json/provider.py", line 230, in dumps
    return json.dumps(obj, **kwargs)
  File "/usr/local/lib/python3.10/json/__init__.py", line 238, in dumps
    **kw).encode(obj)
  File "/usr/local/lib/python3.10/json/encoder.py", line 199, in encode
    chunks = self.iterencode(o, _one_shot=True)
  File "/usr/local/lib/python3.10/json/encoder.py", line 257, in iterencode
    return _iterencode(o, 0)
  File "/home/DriveKraft/.local/lib/python3.10/site-packages/flask/json/provider.py", line 122, in _default
    raise TypeError(f"Object of type {type(o).__name__} is not JSON serializable")
TypeError: Object of type Role is not JSON serializable
